Workbook

Sheet Çalışan Listesi
A1: SİCİL | B1: İSİM SOYİSİM | C1: İŞE GİRİŞ TARİHİ | D1: ORGANİZASYON BİRİMİ | E1: POZİSYON | F1: İŞ | G1: KADEME
A2: 12 | B2: COŞKUN TEKİNASLAN | C2: 33434 | D2: Kısa Elyaf | E2: İhsarat Grup Lideri | F2: GRUP LİDERİ | G2: SÜPERVİZÖR
A3: 15 | B3: MURAT MENTEŞOĞLU | C3: 33451 | D3: Üretim | E3: Üretim Ekip Lideri | F3: ŞEF LİDER | G3: EKİP LİDERİ
A4: 39 | B4: ŞAHİN ŞAHİN | C4: 42954 | D4: Mekanik Bakım | E4: Bakım Ekip Lideri | F4: ŞEF LİDER | G4: EKİP LİDERİ
A5: 42 | B5: ARGÜN KAPLAN | C5: 33569 | D5: Lojistik | E5: Yükleme Boşaltma Opr. (Hammadde) | F5: OPERATÖR | G5: 4.KADEME
A6: 49 | B6: RAMAZAN BALCI | C6: 35760 | D6: Kısa Elyaf | E6: İhsarat Grup Lideri | F6: GRUP LİDERİ | G6: SÜPERVİZÖR
A7: 52 | B7: YAVUZ YILMAM | C7: 35962 | D7: Kısa Elyaf | E7: Ring Bobin Setup Operatörü | F7: OPERATÖR | G7: 3.KADEME
A8: 57 | B8: MUHAMMED GÜMÜŞ | C8: 35485 | D8: Mekanik Bakım | E8: Mekanik Bakım Takım Lideri Yardımcısı | F8: TAKIM LİDERİ YARDIMCISI | G8: 3.KADEME
A9: 64 | B9: MAHMUT MENTEŞ | C9: 34506 | D9: Enerji Bakım | E9: Bakım Ekip Lideri | F9: ŞEF LİDER | G9: EKİP LİDERİ
A10: 72 | B10: MEHMET KÖSE | C10: 36074 | D10: Kısa Elyaf | E10: Makine Temizlik Takım Lideri | F10: TAKIM LİDERİ | G10: 4.KADEME
A11: 73 | B11: VEYSAL DURMUŞ | C11: 34745 | D11: Kısa Elyaf | E11: Ring Bobin Setup Operatörü | F11: OPERATÖR | G11: 3.KADEME
A12: 74 | B12: AKIN ÖZTÜRK | C12: 34771 | D12: Mekanik Bakım | E12: Bakım Ekip Lideri | F12: ŞEF LİDER | G12: EKİP LİDERİ
A13: 79 | B13: AHMET YÖRÜK | C13: 34916 | D13: Kısa Elyaf | E13: İhsarat Grup Lideri | F13: GRUP LİDERİ | G13: SÜPERVİZÖR
... A322: 5372 | B322: SÜLEYMAN DUMAN | C322: 44662 | D322: Ortak İşlemler | E322: Mix Press-Pamuk Hattı Balya Açma Opr | F322: OPERATÖR | G322: 1.KADEME

Sheet Kriter Ağırlık
A1: Kriter | B1: Ağırlık
A2: Kaizen | B2: 0.12 | C2: 0.5
A3: Hata Kartı | B3: 0.1
A4: Bölüm 5S | B4: 0.08
A5: Devamsızlık | B5: 0.1
A6: ISG | B6: 0.1
A7: OEE | B7: 0.35 | C7: 0.5
A8: Telef | B8: 0.15
A11: KIDEM SEVİYESİ | E11: KADEME SEVİYESİ
A12: Personel Kıdem Seviyesi | B12: Personel | C12: Katsayı | E12: Personel Kıdem Seviyesi | F12: Personel | G12: Katsayı
A13: 1 | B13: Şef Müdür | C13: 0 | E13: 1 | F13: KADEME YOK | G13: 1
A14: 2 | B14: Grup Lideri | C14: 0 | E14: 2 | F14: 4.KADEME | G14: 1.232 | K14: =C17/C16 -> 1.3703704
A15: 3 | B15: Takım Lideri | C15: 0 | E15: 3 | F15: 3.KADEME | G15: 1.15
A16: 4 | B16: TL Yardımcı | C16: 13.5 | E16: 4 | F16: 2.KADEME | G16: 1.077
A17: 5 | B17: Operatör | C17: 18.5 | E17: 5 | F17: 1.KADEME | G17: 1
E18: 6 | F18: En 4.Kademe | G18: 1.287
E19: 7 | F19: En 3.Kademe | G19: 1.19
E20: 8 | F20: En 2.Kademe | G20: 1
E21: 9 | F21: En 1.Kademe | G21: 1
E22: 10 | F22: Mek 3.Kademe | G22: 1.378
E23: 11 | F23: Mek 2.Kademe | G23: 1.157
E24: 12 | F24: Mek 1.Kademe | G24: 1

Sheet Devamsızlıklar
A1: SICIL | B1: ADI SOYADI | C1: AMELİYAT | D1: COVİD | E1: DOĞUM | F1: ARA TOPLAM | G1: ORAN | H1: DEVAMSIZLIK | I1: HASTA | J1: İŞ KAZASI | K1: ÜCRETSİZ İZİN | L1: TOPLAM | M1: TOPLAM ORAN | N1: İŞTEKİ GÜN SAYISI
A2: 64 | B2: MAHMUT MENTEŞ | F2: =C2+D2+E2 -> 0 | G2: =F2/90 -> 0 | I2: 5 | L2: =C2+D2+E2+H2+I2+J2+K2 -> 5 | M2: =(N2-L2)/N2 -> 0.94444444 | N2: =IFERROR(VLOOKUP(A2,Sonuç!A:D,4,1),0) -> 90
A3: 73 | B3: VEYSAL DURMUŞ | D3: 6 | F3: =C3+D3+E3 -> 6 | G3: =F3/90 -> 0.066666667 | L3: =C3+D3+E3+H3+I3+J3+K3 -> 6 | M3: =(N3-L3)/N3 -> 0.93333333 | N3: =IFERROR(VLOOKUP(A3,Sonuç!A:D,4,1),0) -> 90
A4: 88 | B4: HAŞİM BAŞARAN | D4: 7 | F4: =C4+D4+E4 -> 7 | G4: =F4/90 -> 0.077777778 | L4: =C4+D4+E4+H4+I4+J4+K4 -> 7 | M4: =(N4-L4)/N4 -> 0.92222222 | N4: =IFERROR(VLOOKUP(A4,Sonuç!A:D,4,1),0) -> 90
A5: 104 | B5: HÜDAİ ELİUZ | F5: =C5+D5+E5 -> 0 | G5: =F5/90 -> 0 | I5: 7 | L5: =C5+D5+E5+H5+I5+J5+K5 -> 7 | M5: =(N5-L5)/N5 -> 0.92222222 | N5: =IFERROR(VLOOKUP(A5,Sonuç!A:D,4,1),0) -> 90
A6: 108 | B6: MUSTAFA EMREM | D6: 6 | F6: =C6+D6+E6 -> 6 | G6: =F6/90 -> 0.066666667 | L6: =C6+D6+E6+H6+I6+J6+K6 -> 6 | M6: =(N6-L6)/N6 -> 0.93333333 | N6: =IFERROR(VLOOKUP(A6,Sonuç!A:D,4,1),0) -> 90
A7: 112 | B7: ALİ DİNGER | D7: 7 | F7: =C7+D7+E7 -> 7 | G7: =F7/90 -> 0.077777778 | L7: =C7+D7+E7+H7+I7+J7+K7 -> 7 | M7: =(N7-L7)/N7 -> 0.92222222 | N7: =IFERROR(VLOOKUP(A7,Sonuç!A:D,4,1),0) -> 90
A8: 125 | B8: RAMAZAN ÖZDEMİR | D8: 7 | F8: =C8+D8+E8 -> 7 | G8: =F8/90 -> 0.077777778 | L8: =C8+D8+E8+H8+I8+J8+K8 -> 7 | M8: =(N8-L8)/N8 -> 0.92222222 | N8: =IFERROR(VLOOKUP(A8,Sonuç!A:D,4,1),0) -> 90
A9: 135 | B9: REMZİ YAVUZ | D9: 7 | F9: =C9+D9+E9 -> 7 | G9: =F9/90 -> 0.077777778 | L9: =C9+D9+E9+H9+I9+J9+K9 -> 7 | M9: =(N9-L9)/N9 -> 0.92222222 | N9: =IFERROR(VLOOKUP(A9,Sonuç!A:D,4,1),0) -> 90
A10: 248 | B10: TUNCAY BAYAM | D10: 7 | F10: =C10+D10+E10 -> 7 | G10: =F10/90 -> 0.077777778 | L10: =C10+D10+E10+H10+I10+J10+K10 -> 7 | M10: =(N10-L10)/N10 -> 0.92222222 | N10: =IFERROR(VLOOKUP(A10,Sonuç!A:D,4,1),0) -> 90
A11: 317 | B11: ENGİN TEKİN | D11: 7 | F11: =C11+D11+E11 -> 7 | G11: =F11/90 -> 0.077777778 | L11: =C11+D11+E11+H11+I11+J11+K11 -> 7 | M11: =(N11-L11)/N11 -> 0.92222222 | N11: =IFERROR(VLOOKUP(A11,Sonuç!A:D,4,1),0) -> 90
A12: 340 | B12: SEVİLAY CEYLAN | D12: 7 | F12: =C12+D12+E12 -> 7 | G12: =F12/90 -> 0.077777778 | L12: =C12+D12+E12+H12+I12+J12+K12 -> 7 | M12: =(N12-L12)/N12 -> 0.92222222 | N12: =IFERROR(VLOOKUP(A12,Sonuç!A:D,4,1),0) -> 90
A13: 380 | B13: RAMAZAN KOÇ | D13: 7 | F13: =C13+D13+E13 -> 7 | G13: =F13/90 -> 0.077777778 | K13: 1 | L13: =C13+D13+E13+H13+I13+J13+K13 -> 8 | M13: =(N13-L13)/N13 -> 0.91111111 | N13: =IFERROR(VLOOKUP(A13,Sonuç!A:D,4,1),0) -> 90
A14: 417 | B14: MEHMET KORT | F14: =C14+D14+E14 -> 0 | G14: =F14/90 -> 0 | I14: 3 | L14: =C14+D14+E14+H14+I14+J14+K14 -> 3 | M14: =(N14-L14)/N14 -> 0.96666667 | N14: =IFERROR(VLOOKUP(A14,Sonuç!A:D,4,1),0) -> 90
A15: 2041 | B15: AZİME YEŞİL | D15: 6 | F15: =C15+D15+E15 -> 6 | G15: =F15/90 -> 0.066666667 | L15: =C15+D15+E15+H15+I15+J15+K15 -> 6 | M15: =(N15-L15)/N15 -> 0.93333333 | N15: =IFERROR(VLOOKUP(A15,Sonuç!A:D,4,1),0) -> 90
A16: 2154 | B16: MAHMUT OĞUR | C16: 43 | F16: =C16+D16+E16 -> 43 | G16: =F16/90 -> 0.47777778 | L16: =C16+D16+E16+H16+I16+J16+K16 -> 43 | M16: =(N16-L16)/N16 -> 0.52222222 | N16: =IFERROR(VLOOKUP(A16,Sonuç!A:D,4,1),0) -> 90
A17: 2280 | B17: ŞERİF SARIKAYA | F17: =C17+D17+E17 -> 0 | G17: =F17/90 -> 0 | I17: 3 | L17: =C17+D17+E17+H17+I17+J17+K17 -> 3 | M17: =(N17-L17)/N17 -> 0.96666667 | N17: =IFERROR(VLOOKUP(A17,Sonuç!A:D,4,1),0) -> 90
A18: 2376 | B18: FERDİ ÖĞMEN | D18: 7 | F18: =C18+D18+E18 -> 7 | G18: =F18/90 -> 0.077777778 | L18: =C18+D18+E18+H18+I18+J18+K18 -> 7 | M18: =(N18-L18)/N18 -> 0.92222222 | N18: =IFERROR(VLOOKUP(A18,Sonuç!A:D,4,1),0) -> 90
A19: 2462 | B19: BEGÜM NARİN | D19: 7 | F19: =C19+D19+E19 -> 7 | G19: =F19/90 -> 0.077777778 | L19: =C19+D19+E19+H19+I19+J19+K19 -> 7 | M19: =(N19-L19)/N19 -> 0.92222222 | N19: =IFERROR(VLOOKUP(A19,Sonuç!A:D,4,1),0) -> 90
A20: 2815 | B20: CEYLAN KURTULMUŞ | F20: =C20+D20+E20 -> 0 | G20: =F20/90 -> 0 | I20: 3 | L20: =C20+D20+E20+H20+I20+J20+K20 -> 3 | M20: =(N20-L20)/N20 -> 0.96666667 | N20: =IFERROR(VLOOKUP(A20,Sonuç!A:D,4,1),0) -> 90
A21: 3111 | B21: MUSTAFA BAYRACI | D21: 7 | F21: =C21+D21+E21 -> 7 | G21: =F21/90 -> 0.077777778 | L21: =C21+D21+E21+H21+I21+J21+K21 -> 7 | M21: =(N21-L21)/N21 -> 0.92222222 | N21: =IFERROR(VLOOKUP(A21,Sonuç!A:D,4,1),0) -> 90
A22: 3113 | B22: PINAR ÇELİK | E22: 37 | F22: =C22+D22+E22 -> 37 | G22: =F22/90 -> 0.41111111 | K22: 53 | L22: =C22+D22+E22+H22+I22+J22+K22 -> 90 | M22: =(N22-L22)/N22 -> 0 | N22: =IFERROR(VLOOKUP(A22,Sonuç!A:D,4,1),0) -> 90
A23: 3438 | B23: AYDIN ÇAĞLAYAN | F23: =C23+D23+E23 -> 0 | G23: =F23/90 -> 0 | I23: 2 | L23: =C23+D23+E23+H23+I23+J23+K23 -> 2 | M23: =(N23-L23)/N23 -> 0.97777778 | N23: =IFERROR(VLOOKUP(A23,Sonuç!A:D,4,1),0) -> 90
A24: 3482 | B24: URKİYE SÜMENOĞLU | D24: 6 | F24: =C24+D24+E24 -> 6 | G24: =F24/90 -> 0.066666667 | L24: =C24+D24+E24+H24+I24+J24+K24 -> 6 | M24: =(N24-L24)/N24 -> 0.93333333 | N24: =IFERROR(VLOOKUP(A24,Sonuç!A:D,4,1),0) -> 90
A25: 3551 | B25: TÜLAY TEKE | D25: 7 | F25: =C25+D25+E25 -> 7 | G25: =F25/90 -> 0.077777778 | L25: =C25+D25+E25+H25+I25+J25+K25 -> 7 | M25: =(N25-L25)/N25 -> 0.92222222 | N25: =IFERROR(VLOOKUP(A25,Sonuç!A:D,4,1),0) -> 90
A26: 3565 | B26: ASİYE OTU | D26: 6 | F26: =C26+D26+E26 -> 6 | G26: =F26/90 -> 0.066666667 | I26: 3 | L26: =C26+D26+E26+H26+I26+J26+K26 -> 9 | M26: =(N26-L26)/N26 -> 0.9 | N26: =IFERROR(VLOOKUP(A26,Sonuç!A:D,4,1),0) -> 90
A27: 3566 | B27: ZEKİ TANDIR | F27: =C27+D27+E27 -> 0 | G27: =F27/90 -> 0 | K27: 2 | L27: =C27+D27+E27+H27+I27+J27+K27 -> 2 | M27: =(N27-L27)/N27 -> 0.97777778 | N27: =IFERROR(VLOOKUP(A27,Sonuç!A:D,4,1),0) -> 90
A28: 3572 | B28: HASAN KÜRKÇÜ | D28: 14 | F28: =C28+D28+E28 -> 14 | G28: =F28/90 -> 0.15555556 | L28: =C28+D28+E28+H28+I28+J28+K28 -> 14 | M28: =(N28-L28)/N28 -> 0.84444444 | N28: =IFERROR(VLOOKUP(A28,Sonuç!A:D,4,1),0) -> 90
A29: 3576 | B29: AHMET YALIN | F29: =C29+D29+E29 -> 0 | G29: =F29/90 -> 0 | K29: 1 | L29: =C29+D29+E29+H29+I29+J29+K29 -> 1 | M29: =(N29-L29)/N29 -> 0.98888889 | N29: =IFERROR(VLOOKUP(A29,Sonuç!A:D,4,1),0) -> 90
A30: 3582 | B30: MUSTAFA ÇIRAK | F30: =C30+D30+E30 -> 0 | G30: =F30/90 -> 0 | I30: 2 | L30: =C30+D30+E30+H30+I30+J30+K30 -> 2 | M30: =(N30-L30)/N30 -> 0.97777778 | N30: =IFERROR(VLOOKUP(A30,Sonuç!A:D,4,1),0) -> 90
A31: 3597 | B31: TUĞBA ŞAĞBAN | F31: =C31+D31+E31 -> 0 | G31: =F31/90 -> 0 | I31: 3 | L31: =C31+D31+E31+H31+I31+J31+K31 -> 3 | M31: =(N31-L31)/N31 -> 0.96666667 | N31: =IFERROR(VLOOKUP(A31,Sonuç!A:D,4,1),0) -> 90
A32: 3598 | B32: SEVİL TEZCAN | F32: =C32+D32+E32 -> 0 | G32: =F32/90 -> 0 | I32: 3 | L32: =C32+D32+E32+H32+I32+J32+K32 -> 3 | M32: =(N32-L32)/N32 -> 0.96666667 | N32: =IFERROR(VLOOKUP(A32,Sonuç!A:D,4,1),0) -> 90
A33: 3614 | B33: FATMA KORKMAZ | F33: =C33+D33+E33 -> 0 | G33: =F33/90 -> 0 | I33: 3 | L33: =C33+D33+E33+H33+I33+J33+K33 -> 3 | M33: =(N33-L33)/N33 -> 0.96666667 | N33: =IFERROR(VLOOKUP(A33,Sonuç!A:D,4,1),0) -> 90
A34: 3656 | B34: ÖMER AKKUŞ | D34: 8 | F34: =C34+D34+E34 -> 8 | G34: =F34/90 -> 0.088888889 | L34: =C34+D34+E34+H34+I34+J34+K34 -> 8 | M34: =(N34-L34)/N34 -> 0.91111111 | N34: =IFERROR(VLOOKUP(A34,Sonuç!A:D,4,1),0) -> 90
A35: 3664 | B35: ERDAL KURTULMUŞ | D35: 6 | F35: =C35+D35+E35 -> 6 | G35: =F35/90 -> 0.066666667 | I35: 3 | L35: =C35+D35+E35+H35+I35+J35+K35 -> 9 | M35: =(N35-L35)/N35 -> 0.9 | N35: =IFERROR(VLOOKUP(A35,Sonuç!A:D,4,1),0) -> 90
A36: 3710 | B36: YUNUS EMRE OTU | D36: 7 | F36: =C36+D36+E36 -> 7 | G36: =F36/90 -> 0.077777778 | L36: =C36+D36+E36+H36+I36+J36+K36 -> 7 | M36: =(N36-L36)/N36 -> 0.92222222 | N36: =IFERROR(VLOOKUP(A36,Sonuç!A:D,4,1),0) -> 90
A37: 3770 | B37: ÖMER PAK | D37: 6 | F37: =C37+D37+E37 -> 6 | G37: =F37/90 -> 0.066666667 | I37: 2 | L37: =C37+D37+E37+H37+I37+J37+K37 -> 8 | M37: =(N37-L37)/N37 -> 0.91111111 | N37: =IFERROR(VLOOKUP(A37,Sonuç!A:D,4,1),0) -> 90
A38: 3805 | B38: ŞEYDA ÖZ | F38: =C38+D38+E38 -> 0 | G38: =F38/90 -> 0 | I38: 1 | J38: 17 | L38: =C38+D38+E38+H38+I38+J38+K38 -> 18 | M38: =(N38-L38)/N38 -> 0.7 | N38: =IFERROR(VLOOKUP(A38,Sonuç!A:D,4,1),0) -> 60
A39: 3807 | B39: HASAN TUFAN GÖÇTÜ | F39: =C39+D39+E39 -> 0 | G39: =F39/90 -> 0 | I39: 5 | L39: =C39+D39+E39+H39+I39+J39+K39 -> 5 | M39: =(N39-L39)/N39 -> 0.94444444 | N39: =IFERROR(VLOOKUP(A39,Sonuç!A:D,4,1),0) -> 90
A40: 3825 | B40: NURAN ÖZÇELİK | F40: =C40+D40+E40 -> 0 | G40: =F40/90 -> 0 | I40: 1 | L40: =C40+D40+E40+H40+I40+J40+K40 -> 1 | M40: =(N40-L40)/N40 -> 0.98888889 | N40: =IFERROR(VLOOKUP(A40,Sonuç!A:D,4,1),0) -> 90
...

Sheet Kaizen Listesi
A1: Personel Sicil No | B1: Personel Adı Soyadı | C1: Bölüm | D1: Pozisyon | E1: Oca | F1: Şub | G1: Mar | H1: ORTALAMA
A2: 12 | B2: COŞKUN TEKİNASLAN | C2: İHSARAT | D2: İhsarat Grup Lideri | E2: 0 | F2: 0 | G2: 0 | H2: =AVERAGE(E2:G2) -> 0
A3: 15 | B3: MURAT MENTEŞOĞLU | C3: RİNG BOBİN | D3: Üretim Ekip Lideri | E3: 0 | F3: 0 | G3: 0 | H3: =AVERAGE(E3:G3) -> 0
A4: 39 | B4: ŞAHİN ŞAHİN | C4: MEKANİK BAKIM | D4: Bakım Ekip Lideri | E4: 0 | F4: 0 | G4: 0 | H4: =AVERAGE(E4:G4) -> 0
A5: 49 | B5: RAMAZAN BALCI | C5: İHSARAT | D5: İhsarat Grup Lideri | E5: 0 | F5: 0 | G5: 0 | H5: =AVERAGE(E5:G5) -> 0
A6: 52 | B6: YAVUZ YILMAM | C6: RİNG BOBİN | D6: Ring Bobin Setup Operatörü | E6: 0 | F6: 0 | G6: 0 | H6: =AVERAGE(E6:G6) -> 0
A7: 57 | B7: MUHAMMED GÜMÜŞ | C7: MEKANİK BAKIM | D7: Mekanik Bakım Takım Lideri Yardımcısı | E7: 0 | F7: 0 | G7: 0 | H7: =AVERAGE(E7:G7) -> 0
A8: 64 | B8: MAHMUT MENTEŞ | C8: ENERJİ BAKIM | D8: Bakım Ekip Lideri | E8: 0 | F8: 0 | G8: 0 | H8: =AVERAGE(E8:G8) -> 0
A9: 72 | B9: MEHMET KÖSE | C9: RİNG BOBİN TEMİZLİK | D9: Makine Temizlik Takım Lideri | E9: 0 | F9: 0 | G9: 0 | H9: =AVERAGE(E9:G9) -> 0
A10: 73 | B10: VEYSAL DURMUŞ | C10: RİNG BOBİN | D10: Ring Bobin Setup Operatörü | E10: 0 | F10: 0 | G10: 0 | H10: =AVERAGE(E10:G10) -> 0
A11: 74 | B11: AKIN ÖZTÜRK | C11: MEKANİK BAKIM | D11: Bakım Ekip Lideri | E11: 0 | F11: 0 | G11: 0 | H11: =AVERAGE(E11:G11) -> 0
A12: 79 | B12: AHMET YÖRÜK | C12: İHSARAT | D12: İhsarat Grup Lideri | E12: 0 | F12: 0 | G12: 0 | H12: =AVERAGE(E12:G12) -> 0
A13: 81 | B13: NURETTİN YILMAM | C13: AMBALAJ | D13: Paketleme Ambalaj Takım Lideri | E13: 0 | F13: 0 | G13: 100 | H13: =AVERAGE(E13:G13) -> 33.333333
... A20: 108 | B20: MUSTAFA EMREM | C20: MEKANİK BAKIM | D20: Mekanik Bakım Takım Lideri | E20: 0 | F20: 100 | G20: 0 | H20: =AVERAGE(E20:G20) -> 33.333333
A21: 109 | B21: RECAİ ELİUZ | C21: RİNG BOBİN | D21: Ring Bobin Setup Takım Lideri Yardımcısı | E21: 100 | F21: 0 | G21: 0 | H21: =AVERAGE(E21:F21) -> 50
A22: 112 | B22: ALİ DİNGER | C22: ENERJİ BAKIM | D22: Elektrik Bakım Takım Lideri | E22: 0 | F22: 0 | G22: 0 | H22: =AVERAGE(E22:G22) -> 0
A23: 113 | B23: MEHMET KÖK | C23: KALİTE | D23: Rektefiye Operatörü | E23: 0 | F23: 0 | G23: 0 | H23: =AVERAGE(E23:G23) -> 0
A24: 120 | B24: ÜMİT ALTINTAŞ | C24: RİNG BOBİN | D24: Ring Bobin Setup Operatörü | E24: 0 | F24: 0 | G24: 0 | H24: =AVERAGE(E24:G24) -> 0
A25: 123 | B25: MUSTAFA BERBEROĞLU | C25: İHSARAT | D25: İhsarat Grup Lideri | E25: 100 | F25: 0 | G25: 100 | H25: =AVERAGE(E25:G25) -> 66.666667
A26: 124 | B26: ALİ KÜÇÜK | C26: AMBALAJ | D26: Paketleme Ambalaj Takım Lideri Yardımcısı | E26: 100 | F26: 0 | G26: 100 | H26: =AVERAGE(E26:G26) -> 66.666667
A27: 125 | B27: RAMAZAN ÖZDEMİR | C27: KALİTE | D27: Proses Kontrol Operatörü | E27: 0 | F27: 0 | G27: 0 | H27: =AVERAGE(E27:G27) -> 0
A28: 129 | B28: ADNAN DAĞLI | C28: KATLAMA BÜKÜM | D28: Katlama Büküm Operatörü | E28: 100 | F28: 100 | G28: 0 | H28: =AVERAGE(E28:G28) -> 66.666667
A29: 131 | B29: ÖZCAN TAŞÇI | C29: RİNG BOBİN | D29: Ring Bobin Setup Takım Lideri | E29: 0 | F29: 100 | G29: 0 | H29: =AVERAGE(E29:F29) -> 50
A30: 135 | B30: REMZİ YAVUZ | C30: KALİTE | D30: Proses Kontrol Operatörü | E30: 100 | F30: 0 | G30: 0 | H30: =AVERAGE(E30:G30) -> 33.333333
A31: 138 | B31: YUSUF SARIOĞLU | C31: KATLAMA BÜKÜM | D31: Katlama Büküm Operatörü | E31: 0 | F31: 0 | G31: 0 | H31: =AVERAGE(E31:G31) -> 0
A32: 146 | B32: VELİ ŞAHBUDAK | C32: KATLAMA BÜKÜM | D32: Katlama Büküm Operatörü | E32: 0 | F32: 0 | G32: 0 | H32: =AVERAGE(E32:G32) -> 0
A33: 149 | B33: POLAT VURAL | C33: İHSARAT | D33: İhsarat Operatörü | E33: 0 | F33: 0 | G33: 0 | H33: =AVERAGE(E33:G33) -> 0
A34: 153 | B34: OSMAN ÇELİK | C34: OPENEND | D34: Open End Katlama Büküm Grup Lideri | E34: 0 | F34: 0 | G34: 0 | H34: =AVERAGE(E34:G34) -> 0
A35: 165 | B35: HALİL DURAN | C35: İHSARAT | D35: İhsarat Takım Lideri Yardımcısı | E35: 0 | F35: 0 | G35: 0 | H35: =AVERAGE(E35:G35) -> 0
A36: 171 | B36: MUHTEREM YAVUZ | C36: İHSARAT | D36: İhsarat Operatörü | E36: 0 | F36: 0 | G36: 0 | H36: =AVERAGE(E36:G36) -> 0
A37: 215 | B37: AHMET ŞENAY | C37: RİNG BOBİN | D37: Ring Bobin Grup Lideri | E37: 0 | F37: 0 | G37: 100 | H37: =AVERAGE(E37:G37) -> 33.333333
A38: 218 | B38: GÜNAY ERİN | C38: RİNG BOBİN | D38: Ring Bobin Operatörü | E38: 0 | F38: 0 | G38: 0 | H38: =AVERAGE(E38:G38) -> 0
A39: 219 | B39: MUSTAFA BALIK | C39: RİNG BOBİN | D39: Ring Bobin Setup Operatörü | E39: 0 | F39: 100 | G39: 0 | H39: =AVERAGE(E39:G39) -> 33.333333
A40: 225 | B40: SÜLEYMAN YILDIRIM | C40: RİNG BOBİN | D40: Open End Ring Bobin ve Setup Lideri | E40: 0 | F40: 0 | G40: 0 | H40: =AVERAGE(E40:F40) -> 0
A41: 227 | B41: ZÜHTÜ GÜNDAĞ | C41: RİNG BOBİN | D41: Ring Bobin Setup Operatörü | E41: 0 | F41: 0 | G41: 0 | H41: =AVERAGE(E41:G41) -> 0
A42: 230 | B42: İLYAS ORHAN | C42: OPENEND | D42: Open End Katlama Büküm Grup Lideri | E42: 0 | F42: 0 | G42: 0 | H42: =AVERAGE(E42:G42) -> 0
A43: 231 | B43: ŞEVKİ DEMİR | C43: RİNG BOBİN | D43: Ring Bobin Setup Operatörü | E43: 0 | F43: 0 | G43: 0 | H43: =AVERAGE(E43:G43) -> 0
A44: 239 | B44: ÜMİT ÇOBAN | C44: MİX PRESE-PAMUK | D44: Pamuk Mix Prese Takım Lideri | E44: 0 | F44: 0 | G44: 100 | H44: =AVERAGE(E44:G44) -> 33.333333
A45: 248 | B45: TUNCAY BAYAM | C45: RİNG BOBİN | D45: Ring Bobin Setup Operatörü | E45: 0 | F45: 0 | G45: 0 | H45: =AVERAGE(E45:G45) -> 0
A46: 253 | B46: AHMET MULCAR | C46: RİNG BOBİN | D46: Open End Ring Bobin ve Setup Lideri | E46: 0 | F46: 0 | G46: 100 | H46: =AVERAGE(E46:G46) -> 33.333333
...

Sheet Hata Kartı 
A1: Sicil No | B1: Personel Adı Soyadı | C1: Bölüm | D1: Pozisyon | E1: Oca | F1: Şub | G1: Mar | H1: ORTALAMA
A2: 12 | B2: COŞKUN TEKİNASLAN | C2: İHSARAT | D2: İhsarat Grup Lideri | E2: 0 | F2: 0 | G2: 0 | H2: =AVERAGE(E2:G2) -> 0
A3: 15 | B3: MURAT MENTEŞOĞLU | C3: RİNG BOBİN | D3: Üretim Ekip Lideri | E3: 0 | F3: 50 | G3: 0 | H3: =AVERAGE(E3:G3) -> 16.666667
A4: 39 | B4: ŞAHİN ŞAHİN | C4: MEKANİK BAKIM | D4: Bakım Ekip Lideri | E4: 0 | F4: 0 | G4: 0 | H4: =AVERAGE(E4:G4) -> 0
A5: 49 | B5: RAMAZAN BALCI | C5: İHSARAT | D5: İhsarat Grup Lideri | E5: 0 | F5: 0 | G5: 0 | H5: =AVERAGE(E5:G5) -> 0
A6: 52 | B6: YAVUZ YILMAM | C6: RİNG BOBİN | D6: Ring Bobin Setup Operatörü | E6: 0 | F6: 0 | G6: 0 | H6: =AVERAGE(E6:G6) -> 0
A7: 57 | B7: MUHAMMED GÜMÜŞ | C7: MEKANİK BAKIM | D7: Mekanik Bakım Takım Lideri Yardımcısı | E7: 100 | F7: 100 | G7: 0 | H7: =AVERAGE(E7:G7) -> 66.666667
A8: 64 | B8: MAHMUT MENTEŞ | C8: ENERJİ BAKIM | D8: Bakım Ekip Lideri | E8: 0 | F8: 50 | G8: 0 | H8: =AVERAGE(E8:G8) -> 16.666667
A9: 72 | B9: MEHMET KÖSE | C9: RİNG BOBİN TEMİZLİK | D9: Makine Temizlik Takım Lideri | E9: 100 | F9: 100 | G9: 100 | H9: =AVERAGE(E9:G9) -> 100
A10: 73 | B10: VEYSAL DURMUŞ | C10: RİNG BOBİN | D10: Ring Bobin Setup Operatörü | E10: 0 | F10: 0 | G10: 0 | H10: =AVERAGE(E10:G10) -> 0
A11: 74 | B11: AKIN ÖZTÜRK | C11: MEKANİK BAKIM | D11: Bakım Ekip Lideri | E11: 0 | F11: 0 | G11: 0 | H11: =AVERAGE(E11:G11) -> 0
A12: 79 | B12: AHMET YÖRÜK | C12: İHSARAT | D12: İhsarat Grup Lideri | E12: 0 | F12: 0 | G12: 0 | H12: =AVERAGE(E12:G12) -> 0
A13: 81 | B13: NURETTİN YILMAM | C13: AMBALAJ | D13: Paketleme Ambalaj Takım Lideri | E13: 0 | F13: 0 | G13: 100 | H13: =AVERAGE(E13:G13) -> 33.333333
... A20: 108 | B20: MUSTAFA EMREM | C20: MEKANİK BAKIM | D20: Mekanik Bakım Takım Lideri | E20: 0 | F20: 0 | G20: 0 | H20: =AVERAGE(E20:G20) -> 0
A21: 109 | B21: RECAİ ELİUZ | C21: RİNG BOBİN | D21: Ring Bobin Setup Takım Lideri Yardımcısı | E21: 0 | F21: 100 | G21: 0 | H21: =AVERAGE(E21:F21) -> 50
A22: 112 | B22: ALİ DİNGER | C22: ENERJİ BAKIM | D22: Elektrik Bakım Takım Lideri | E22: 0 | F22: 0 | G22: 0 | H22: =AVERAGE(E22:G22) -> 0
A23: 113 | B23: MEHMET KÖK | C23: KALİTE | D23: Rektefiye Operatörü | E23: 100 | F23: 0 | G23: 100 | H23: =AVERAGE(E23:G23) -> 66.666667
A24: 120 | B24: ÜMİT ALTINTAŞ | C24: RİNG BOBİN | D24: Ring Bobin Setup Operatörü | E24: 0 | F24: 100 | G24: 0 | H24: =AVERAGE(E24:G24) -> 33.333333
A25: 123 | B25: MUSTAFA BERBEROĞLU | C25: İHSARAT | D25: İhsarat Grup Lideri | E25: 0 | F25: 100 | G25: 0 | H25: =AVERAGE(E25:G25) -> 33.333333
A26: 124 | B26: ALİ KÜÇÜK | C26: AMBALAJ | D26: Paketleme Ambalaj Takım Lideri Yardımcısı | E26: 100 | F26: 100 | G26: 100 | H26: =AVERAGE(E26:G26) -> 100
A27: 125 | B27: RAMAZAN ÖZDEMİR | C27: KALİTE | D27: Proses Kontrol Operatörü | E27: 100 | F27: 100 | G27: 100 | H27: =AVERAGE(E27:G27) -> 100
A28: 129 | B28: ADNAN DAĞLI | C28: KATLAMA BÜKÜM | D28: Katlama Büküm Operatörü | E28: 100 | F28: 100 | G28: 50 | H28: =AVERAGE(E28:G28) -> 83.333333
A29: 131 | B29: ÖZCAN TAŞÇI | C29: RİNG BOBİN | D29: Ring Bobin Setup Takım Lideri | E29: 100 | F29: 0 | G29: 0 | H29: =AVERAGE(E29:F29) -> 50
A30: 135 | B30: REMZİ YAVUZ | C30: KALİTE | D30: Proses Kontrol Operatörü | E30: 100 | F30: 100 | G30: 0 | H30: =AVERAGE(E30:G30) -> 66.666667
A31: 138 | B31: YUSUF SARIOĞLU | C31: KATLAMA BÜKÜM | D31: Katlama Büküm Operatörü | E31: 0 | F31: 0 | G31: 0 | H31: =AVERAGE(E31:G31) -> 0
A32: 146 | B32: VELİ ŞAHBUDAK | C32: KATLAMA BÜKÜM | D32: Katlama Büküm Operatörü | E32: 0 | F32: 0 | G32: 0 | H32: =AVERAGE(E32:G32) -> 0
A33: 149 | B33: POLAT VURAL | C33: İHSARAT | D33: İhsarat Operatörü | E33: 0 | F33: 0 | G33: 0 | H33: =AVERAGE(E33:G33) -> 0
A34: 153 | B34: OSMAN ÇELİK | C34: OPENEND | D34: Open End Katlama Büküm Grup Lideri | E34: 0 | F34: 0 | G34: 0 | H34: =AVERAGE(E34:G34) -> 0
A35: 165 | B35: HALİL DURAN | C35: İHSARAT | D35: İhsarat Takım Lideri Yardımcısı | E35: 100 | F35: 0 | G35: 50 | H35: =AVERAGE(E35:G35) -> 50
A36: 171 | B36: MUHTEREM YAVUZ | C36: İHSARAT | D36: İhsarat Operatörü | E36: 0 | F36: 0 | G36: 0 | H36: =AVERAGE(E36:G36) -> 0
A37: 215 | B37: AHMET ŞENAY | C37: RİNG BOBİN | D37: Ring Bobin Grup Lideri | E37: 50 | F37: 0 | G37: 0 | H37: =AVERAGE(E37:G37) -> 16.666667
A38: 218 | B38: GÜNAY ERİN | C38: RİNG BOBİN | D38: Ring Bobin Operatörü | E38: 100 | F38: 100 | G38: 100 | H38: =AVERAGE(E38:G38) -> 100
A39: 219 | B39: MUSTAFA BALIK | C39: RİNG BOBİN | D39: Ring Bobin Setup Operatörü | E39: 0 | F39: 50 | G39: 0 | H39: =AVERAGE(E39:G39) -> 16.666667
A40: 225 | B40: SÜLEYMAN YILDIRIM | C40: RİNG BOBİN | D40: Open End Ring Bobin ve Setup Lideri | E40: 100 | F40: 50 | G40: 0 | H40: =AVERAGE(E40:F40) -> 75
A41: 227 | B41: ZÜHTÜ GÜNDAĞ | C41: RİNG BOBİN | D41: Ring Bobin Setup Operatörü | E41: 50 | F41: 100 | G41: 0 | H41: =AVERAGE(E41:G41) -> 50
A42: 230 | B42: İLYAS ORHAN | C42: OPENEND | D42: Open End Katlama Büküm Grup Lideri | E42: 0 | F42: 0 | G42: 0 | H42: =AVERAGE(E42:G42) -> 0
A43: 231 | B43: ŞEVKİ DEMİR | C43: RİNG BOBİN | D43: Ring Bobin Setup Operatörü | E43: 100 | F43: 100 | G43: 0 | H43: =AVERAGE(E43:G43) -> 66.666667
A44: 239 | B44: ÜMİT ÇOBAN | C44: MİX PRESE-PAMUK | D44: Pamuk Mix Prese Takım Lideri | E44: 100 | F44: 0 | G44: 0 | H44: =AVERAGE(E44:G44) -> 33.333333
A45: 248 | B45: TUNCAY BAYAM | C45: RİNG BOBİN | D45: Ring Bobin Setup Operatörü | E45: 0 | F45: 100 | G45: 0 | H45: =AVERAGE(E45:G45) -> 33.333333
A46: 253 | B46: AHMET MULCAR | C46: RİNG BOBİN | D46: Open End Ring Bobin ve Setup Lideri | E46: 50 | F46: 0 | G46: 0 | H46: =AVERAGE(E46:G46) -> 16.666667
...

Sheet Aralıklar
A2: İSG | E2: MAZERETSİZ | I2: HASTA | M2: ÜCRETSİZ İZİN
A3: Baş. | B3: Bitiş | C3: Puan | E3: Baş. | F3: Bitiş | G3: Puan | I3: Baş. | J3: Bitiş | K3: Puan | M3: Baş. | N3: Bitiş | O3: Puan
A4: 0 | B4: 0 | C4: 100 | E4: 0 | F4: 0 | G4: 1 | I4: 0 | J4: 3 | K4: 50 | M4: 0 | N4: 1 | O4: 50
A5: 0.01 | B5: 100 | C5: 0 | E5: 0.01 | F5: 90 | G5: 0 | I5: 3.01 | J5: 6 | K5: 25 | M5: 1.01 | N5: 2 | O5: 25
I6: 6.01 | J6: 90 | K6: 0 | M6: 2.01 | N6: 90 | O6: 0

Sheet 5S
B7: BÖLÜM | C7: HEDEF | D7: GERÇEKLEŞEN | E7: GERÇEK / HEDEF | G7: BÖLÜM 5S PUAN ARALIK
B8: AMBALAJ | C8: 50 | D8: 50 | E8: =D8/C8 -> 1 | G8: BAŞ | H8: BİTİŞ | I8: PUAN
B9: ENERJİ | C9: 60 | D9: 60 | E9: =D9/C9 -> 1 | G9: 0 | H9: 0 | I9: 0
B10: LOJİSTİK | C10: 60 | D10: 60 | E10: =D10/C10 -> 1 | G10: 0.01 | H10: 0.24 | I10: 10
B11: İHSARAT | C11: 50 | D11: 50 | E11: =D11/C11 -> 1 | G11: 0.25 | H11: 0.49 | I11: 30
B12: RİNG BOBİN | C12: 60 | D12: 60 | E12: =D12/C12 -> 1 | G12: 0.5 | H12: 0.74 | I12: 50
B13: MEKANİK | C13: 30 | D13: 30 | E13: =D13/C13 -> 1 | G13: 0.75 | H13: 0.89 | I13: 70
B14: MAKİNE TEMİZLİK | C14: 60 | D14: 60 | E14: =D14/C14 -> 1 | G14: 0.9 | H14: 1 | I14: 100
B15: KATLAMA BÜKÜM | C15: 60 | D15: 60 | E15: =D15/C15 -> 1
B16: KALİTE | C16: 60 | D16: 60 | E16: =D16/C16 -> 1
B17: OPENEND | C17: 45 | D17: 45 | E17: =D17/C17 -> 1
B18: TEMİZLİK | C18: 70 | D18: 70 | E18: =D18/C18 -> 1
B19: MİX PAMUK | C19: 50 | D19: 50 | E19: =D19/C19 -> 1

Sheet OEE
A2: Başlangıç | B2: Bitiş | C2: Puanı | E2: Bölüm | F2: HEDEF | G2: GERÇEKLEŞEN | H2: GERÇEKLEŞTİRME/HEDEF | I2: OEE KATSAYISI | J2: AĞIRLIK KATSAYISI | K2: AĞIRLIK ORTALAMA
E3: SS | F3: 93.5 | G3: 93.5 | H3: =G3/F3 -> 1 | I3: =VLOOKUP(H3,A2:C11,3,1) -> 100 | J3: 0.85 | K3: =I3*J3 -> 85
A4: 0 | B4: 0.971 | C4: 0 | E4: OE | F4: 70 | G4: 70 | H4: =G4/F4 -> 1 | I4: =VLOOKUP(H4,A3:C12,3,1) -> 100 | J4: 0.1 | K4: =I4*J4 -> 10
A5: 0.972 | B5: 0.977 | C5: 10 | E5: BÜKÜM | F5: 93.5 | G5: 93.5 | H5: =G5/F5 -> 1 | I5: =VLOOKUP(H5,A4:C13,3,1) -> 100 | J5: 0.05 | K5: =I5*J5 -> 5
A6: 0.978 | B6: 0.982 | C6: 30 | J6: OEE PUAN | K6: =SUM(K3:K5) -> 100
A7: 0.983 | B7: 0.987 | C7: 50
A8: 0.988 | B8: 0.993 | C8: 70
A9: 0.994 | B9: 0.999 | C9: 90
A10: 1 | B10: 5 | C10: 100

Sheet TELEF
A1: TELEF
A2: başlangıç | B2: bitiş | C2: Katsayısı
A4: 0 | B4: 1.054 | C4: 100
A5: 1.055 | B5: 1.08 | C5: 90 | E5: Bölüm | F5: HEDEF | G5: GERÇEKLEŞEN | H5: GERÇEK / HEDEF | I5: TELEF KATSAYISI
A6: 1.081 | B6: 1.106 | C6: 80 | E6: Fitil Açma Telefi (PK) Miktarı % | F6: 0.09
A7: 1.107 | B7: 1.133 | C7: 60 | E7: Pnömofil Telefi (PK) Miktarı % | F7: 0.92
A8: 1.134 | B8: 1.159 | C8: 40 | E8: Üstübü Telefi (PU) Miktarı % | F8: 0.81
A9: 1.16 | B9: 1.21 | C9: 15 | E9: Kops Sıyırma Telefi (PU) Miktarı % | F9: 0.17
A10: 1.2105 | B10: 1.5 | C10: 0 | E10: TOPLAM TELEF | F10: =SUM(F6:F9) -> 1.99 | G10: 1.99 | H10: =G10/F10 -> 1 | I10: =VLOOKUP(H10,A1:C11,3,1) -> 100

Sheet Sonuç
U1: 72.498494 | AA1: =AVERAGE(AA3:AA319) -> 72.512461 | AI1: =AA1 -> 72.512461
A2: Personel numarası | B2: Personel numarası | C2: İşe giriş | D2: 90 günlük periyot | E2: GÜNLÜK KATSAYISI | F2: BÖLÜM | G2: Pozisyon | H2: KADEME | I2: Kaizen | J2: Kaizen Puan | K2: Hata Kartı | L2: Hata Kartı Puan | M2: Bölüm 5S | N2: 5S Puan | O2: ISG | P2: ISG PUAN | Q2: Devamsızlık | R2: Dev.Puan | S2: Hasta | T2: Hasta Puan | U2: Ücretsiz İzin | V2: Ücretsiz İzin Puan | W2: Devamsızlık | X2: DEVAM ORANI | Y2: OEE | Z2: Telef | AA2: PERFORMANS PUANI | AB2: Pozisyon Seviyesi | AC2: Pozisyon katsayısı | AD2: Kademe Seviyesi | AE2: Kademe katsayısı | AF2: SONUÇ | AG2: GÖREV | AI2: 44651
A3: 12 | B3: COŞKUN TEKİNASLAN | C3: 33434 | D3: =IF($AI$2-C3>=90,90,$AI$2-C3) -> 90 | E3: =D3/90 -> 1 | F3: İHSARAT | G3: İhsarat Grup Lideri | H3: =VLOOKUP(A3,'Çalışan Listesi'!A:G,7,0) -> SÜPERVİZÖR | I3: =IFERROR(VLOOKUP(A3,'Kaizen Listesi'!A:H,8,0),0) -> 0 | J3: =I3*VLOOKUP($I$2,'Kriter Ağırlık'!$A$1:$B$8,2,0) -> 0 | K3: =IFERROR(VLOOKUP(A3,'Hata Kartı '!A:H,8,0),0) -> 0 | L3: =K3*(VLOOKUP($K$2,'Kriter Ağırlık'!$A$1:$B$8,2,0)) -> 0 | M3: =IFERROR(VLOOKUP(F3,'5S'!$B$8:$E$19,4,0),0) -> 1 | N3: =VLOOKUP(M3,'5S'!$G$8:$I$14,3,1)*VLOOKUP($M$2,'Kriter Ağırlık'!$A$1:$B$8,2,0)*E3*X3 -> 8 | O3: =IFERROR(VLOOKUP(A3,Devamsızlıklar!A:K,10,0),0) -> 0 | P3: =VLOOKUP(O3,Aralıklar!$A$2:$C$5,3,1)*VLOOKUP($O$2,'Kriter Ağırlık'!$A$1:$B$8,2,0)*E3*X3 -> 10 | Q3: =IFERROR(VLOOKUP(A3,Devamsızlıklar!A:K,8,0),0) -> 0 | R3: =VLOOKUP(Q3,Aralıklar!$E$2:$G$5,3,1) -> 1 | S3: =IFERROR(VLOOKUP(A3,Devamsızlıklar!A:K,9,0),0) -> 0 | T3: =VLOOKUP(S3,Aralıklar!$I$2:$K$6,3,1) -> 50 | U3: =IFERROR(VLOOKUP(A3,Devamsızlıklar!A:K,11,0),0) -> 0 | V3: =VLOOKUP(U3,Aralıklar!$M$2:$O$6,3,1) -> 50 | W3: =IF(X3=0,0,(T3+V3)*R3*VLOOKUP($W$2,'Kriter Ağırlık'!$A$1:$B$8,2,1)*E3) -> 10 | X3: =IFERROR(VLOOKUP(A3,Devamsızlıklar!A:M,13,0),1) -> 1 | Y3: =(OEE!$K$6*VLOOKUP($Y$2,'Kriter Ağırlık'!$A$1:$B$8,2,1))*X3*E3 -> 35 | Z3: =(TELEF!$I$10*VLOOKUP($Z$2,'Kriter Ağırlık'!$A$1:$B$8,2,1))*X3*E3 -> 15 | AA3: =J3+L3+N3+P3+W3+Y3+Z3 -> 78 | AB3: 2 | AC3: =VLOOKUP(AB3,'Kriter Ağırlık'!$A$12:$C$17,3,0) -> 0 | AD3: 1 | AE3: =VLOOKUP(AD3,'Kriter Ağırlık'!$E$12:$G$24,3,0) -> 1 | AF3: =AA3*AC3*AE3 -> 0 | AG3: =VLOOKUP(A3,'Çalışan Listesi'!A:G,6,0) -> GRUP LİDERİ
A4: 15 | B4: MURAT MENTEŞOĞLU | C4: 33451 | D4: =IF($AI$2-C4>=90,90,$AI$2-C4) -> 90 | E4: =D4/90 -> 1 | F4: ÜRETİM | G4: Üretim Ekip Lideri | H4: =VLOOKUP(A4,'Çalışan Listesi'!A:G,7,0) -> EKİP LİDERİ | I4: =IFERROR(VLOOKUP(A4,'Kaizen Listesi'!A:H,8,0),0) -> 0 | J4: =I4*VLOOKUP($I$2,'Kriter Ağırlık'!$A$1:$B$8,2,0) -> 0 | K4: =IFERROR(VLOOKUP(A4,'Hata Kartı '!A:H,8,0),0) -> 16.666667 | L4: =K4*(VLOOKUP($K$2,'Kriter Ağırlık'!$A$1:$B$8,2,0)) -> 1.6666667 | M4: =IFERROR(VLOOKUP(F4,'5S'!$B$8:$E$19,4,0),0) -> 0 | N4: =VLOOKUP(M4,'5S'!$G$8:$I$14,3,1)*VLOOKUP($M$2,'Kriter Ağırlık'!$A$1:$B$8,2,0)*E4*X4 -> 0 | O4: =IFERROR(VLOOKUP(A4,Devamsızlıklar!A:K,10,0),0) -> 0 | P4: =VLOOKUP(O4,Aralıklar!$A$2:$C$5,3,1)*VLOOKUP($O$2,'Kriter Ağırlık'!$A$1:$B$8,2,0)*E4*X4 -> 10 | Q4: =IFERROR(VLOOKUP(A4,Devamsızlıklar!A:K,8,0),0) -> 0 | R4: =VLOOKUP(Q4,Aralıklar!$E$2:$G$5,3,1) -> 1 | S4: =IFERROR(VLOOKUP(A4,Devamsızlıklar!A:K,9,0),0) -> 0 | T4: =VLOOKUP(S4,Aralıklar!$I$2:$K$6,3,1) -> 50 | U4: =IFERROR(VLOOKUP(A4,Devamsızlıklar!A:K,11,0),0) -> 0 | V4: =VLOOKUP(U4,Aralıklar!$M$2:$O$6,3,1) -> 50 | W4: =IF(X4=0,0,(T4+V4)*R4*VLOOKUP($W$2,'Kriter Ağırlık'!$A$1:$B$8,2,1)*E4) -> 10 | X4: =IFERROR(VLOOKUP(A4,Devamsızlıklar!A:M,13,0),1) -> 1 | Y4: =(OEE!$K$6*VLOOKUP($Y$2,'Kriter Ağırlık'!$A$1:$B$8,2,1))*X4*E4 -> 35 | Z4: =(TELEF!$I$10*VLOOKUP($Z$2,'Kriter Ağırlık'!$A$1:$B$8,2,1))*X4*E4 -> 15 | AA4: =J4+L4+N4+P4+W4+Y4+Z4 -> 71.666667 | AB4: 1 | AC4: =VLOOKUP(AB4,'Kriter Ağırlık'!$A$12:$C$17,3,0) -> 0 | AD4: 1 | AE4: =VLOOKUP(AD4,'Kriter Ağırlık'!$E$12:$G$24,3,0) -> 1 | AF4: =AA4*AC4*AE4 -> 0 | AG4: =VLOOKUP(A4,'Çalışan Listesi'!A:G,6,0) -> ŞEF LİDER
A5: 39 | B5: ŞAHİN ŞAHİN | C5: 42954 | D5: =IF($AI$2-C5>=90,90,$AI$2-C5) -> 90 | E5: =D5/90 -> 1 | F5: MEKANİK | G5: Bakım Ekip Lideri | H5: =VLOOKUP(A5,'Çalışan Listesi'!A:G,7,0) -> EKİP LİDERİ | I5: =IFERROR(VLOOKUP(A5,'Kaizen Listesi'!A:H,8,0),0) -> 0 | J5: =I5*VLOOKUP($I$2,'Kriter Ağırlık'!$A$1:$B$8,2,0) -> 0 | K5: =IFERROR(VLOOKUP(A5,'Hata Kartı '!A:H,8,0),0) -> 0 | L5: =K5*(VLOOKUP($K$2,'Kriter Ağırlık'!$A$1:$B$8,2,0)) -> 0 | M5: =IFERROR(VLOOKUP(F5,'5S'!$B$8:$E$19,4,0),0) -> 1 | N5: =VLOOKUP(M5,'5S'!$G$8:$I$14,3,1)*VLOOKUP($M$2,'Kriter Ağırlık'!$A$1:$B$8,2,0)*E5*X5 -> 8 | O5: =IFERROR(VLOOKUP(A5,Devamsızlıklar!A:K,10,0),0) -> 0 | P5: =VLOOKUP(O5,Aralıklar!$A$2:$C$5,3,1)*VLOOKUP($O$2,'Kriter Ağırlık'!$A$1:$B$8,2,0)*E5*X5 -> 10 | Q5: =IFERROR(VLOOKUP(A5,Devamsızlıklar!A:K,8,0),0) -> 0 | R5: =VLOOKUP(Q5,Aralıklar!$E$2:$G$5,3,1) -> 1 | S5: =IFERROR(VLOOKUP(A5,Devamsızlıklar!A:K,9,0),0) -> 0 | T5: =VLOOKUP(S5,Aralıklar!$I$2:$K$6,3,1) -> 50 | U5: =IFERROR(VLOOKUP(A5,Devamsızlıklar!A:K,11,0),0) -> 0 | V5: =VLOOKUP(U5,Aralıklar!$M$2:$O$6,3,1) -> 50 | W5: =IF(X5=0,0,(T5+V5)*R5*VLOOKUP($W$2,'Kriter Ağırlık'!$A$1:$B$8,2,1)*E5) -> 10 | X5: =IFERROR(VLOOKUP(A5,Devamsızlıklar!A:M,13,0),1) -> 1 | Y5: =(OEE!$K$6*VLOOKUP($Y$2,'Kriter Ağırlık'!$A$1:$B$8,2,1))*X5*E5 -> 35 | Z5: =(TELEF!$I$10*VLOOKUP($Z$2,'Kriter Ağırlık'!$A$1:$B$8,2,1))*X5*E5 -> 15 | AA5: =J5+L5+N5+P5+W5+Y5+Z5 -> 78 | AB5: 1 | AC5: =VLOOKUP(AB5,'Kriter Ağırlık'!$A$12:$C$17,3,0) -> 0 | AD5: 1 | AE5: =VLOOKUP(AD5,'Kriter Ağırlık'!$E$12:$G$24,3,0) -> 1 | AF5: =AA5*AC5*AE5 -> 0 | AG5: =VLOOKUP(A5,'Çalışan Listesi'!A:G,6,0) -> ŞEF LİDER
A6: 42 | B6: ARGÜN KAPLAN | C6: 33569 | D6: =IF($AI$2-C6>=90,90,$AI$2-C6) -> 90 | E6: =D6/90 -> 1 | F6: LOJİSTİK | G6: Yükleme Boşaltma Opr. (Hammadde) | H6: =VLOOKUP(A6,'Çalışan Listesi'!A:G,7,0) -> 4.KADEME | I6: =IFERROR(VLOOKUP(A6,'Kaizen Listesi'!A:H,8,0),0) -> 0 | J6: =I6*VLOOKUP($I$2,'Kriter Ağırlık'!$A$1:$B$8,2,0) -> 0 | K6: =IFERROR(VLOOKUP(A6,'Hata Kartı '!A:H,8,0),0) -> 0 | L6: =K6*(VLOOKUP($K$2,'Kriter Ağırlık'!$A$1:$B$8,2,0)) -> 0 | M6: =IFERROR(VLOOKUP(F6,'5S'!$B$8:$E$19,4,0),0) -> 1 | N6: =VLOOKUP(M6,'5S'!$G$8:$I$14,3,1)*VLOOKUP($M$2,'Kriter Ağırlık'!$A$1:$B$8,2,0)*E6*X6 -> 8 | O6: =IFERROR(VLOOKUP(A6,Devamsızlıklar!A:K,10,0),0) -> 0 | P6: =VLOOKUP(O6,Aralıklar!$A$2:$C$5,3,1)*VLOOKUP($O$2,'Kriter Ağırlık'!$A$1:$B$8,2,0)*E6*X6 -> 10 | Q6: =IFERROR(VLOOKUP(A6,Devamsızlıklar!A:K,8,0),0) -> 0 | R6: =VLOOKUP(Q6,Aralıklar!$E$2:$G$5,3,1) -> 1 | S6: =IFERROR(VLOOKUP(A6,Devamsızlıklar!A:K,9,0),0) -> 0 | T6: =VLOOKUP(S6,Aralıklar!$I$2:$K$6,3,1) -> 50 | U6: =IFERROR(VLOOKUP(A6,Devamsızlıklar!A:K,11,0),0) -> 0 | V6: =VLOOKUP(U6,Aralıklar!$M$2:$O$6,3,1) -> 50 | W6: =IF(X6=0,0,(T6+V6)*R6*VLOOKUP($W$2,'Kriter Ağırlık'!$A$1:$B$8,2,1)*E6) -> 10 | X6: =IFERROR(VLOOKUP(A6,Devamsızlıklar!A:M,13,0),1) -> 1 | Y6: =(OEE!$K$6*VLOOKUP($Y$2,'Kriter Ağırlık'!$A$1:$B$8,2,1))*X6*E6 -> 35 | Z6: =(TELEF!$I$10*VLOOKUP($Z$2,'Kriter Ağırlık'!$A$1:$B$8,2,1))*X6*E6 -> 15 | AA6: =J6+L6+N6+P6+W6+Y6+Z6 -> 78 | AB6: 5 | AC6: =VLOOKUP(AB6,'Kriter Ağırlık'!$A$12:$C$17,3,0) -> 18.5 | AD6: 2 | AE6: =VLOOKUP(AD6,'Kriter Ağırlık'!$E$12:$G$24,3,0) -> 1.232 | AF6: =AA6*AC6*AE6 -> 1777.776 | AG6: =VLOOKUP(A6,'Çalışan Listesi'!A:G,6,0) -> OPERATÖR
A7: 49 | B7: RAMAZAN BALCI | C7: 35760 | D7: =IF($AI$2-C7>=90,90,$AI$2-C7) -> 90 | E7: =D7/90 -> 1 | F7: İHSARAT | G7: İhsarat Grup Lideri | H7: =VLOOKUP(A7,'Çalışan Listesi'!A:G,7,0) -> SÜPERVİZÖR | I7: =IFERROR(VLOOKUP(A7,'Kaizen Listesi'!A:H,8,0),0) -> 0 | J7: =I7*VLOOKUP($I$2,'Kriter Ağırlık'!$A$1:$B$8,2,0) -> 0 | K7: =IFERROR(VLOOKUP(A7,'Hata Kartı '!A:H,8,0),0) -> 0 | L7: =K7*(VLOOKUP($K$2,'Kriter Ağırlık'!$A$1:$B$8,2,0)) -> 0 | M7: =IFERROR(VLOOKUP(F7,'5S'!$B$8:$E$19,4,0),0) -> 1 | N7: =VLOOKUP(M7,'5S'!$G$8:$I$14,3,1)*VLOOKUP($M$2,'Kriter Ağırlık'!$A$1:$B$8,2,0)*E7*X7 -> 8 | O7: =IFERROR(VLOOKUP(A7,Devamsızlıklar!A:K,10,0),0) -> 0 | P7: =VLOOKUP(O7,Aralıklar!$A$2:$C$5,3,1)*VLOOKUP($O$2,'Kriter Ağırlık'!$A$1:$B$8,2,0)*E7*X7 -> 10 | Q7: =IFERROR(VLOOKUP(A7,Devamsızlıklar!A:K,8,0),0) -> 0 | R7: =VLOOKUP(Q7,Aralıklar!$E$2:$G$5,3,1) -> 1 | S7: =IFERROR(VLOOKUP(A7,Devamsızlıklar!A:K,9,0),0) -> 0 | T7: =VLOOKUP(S7,Aralıklar!$I$2:$K$6,3,1) -> 50 | U7: =IFERROR(VLOOKUP(A7,Devamsızlıklar!A:K,11,0),0) -> 0 | V7: =VLOOKUP(U7,Aralıklar!$M$2:$O$6,3,1) -> 50 | W7: =IF(X7=0,0,(T7+V7)*R7*VLOOKUP($W$2,'Kriter Ağırlık'!$A$1:$B$8,2,1)*E7) -> 10 | X7: =IFERROR(VLOOKUP(A7,Devamsızlıklar!A:M,13,0),1) -> 1 | Y7: =(OEE!$K$6*VLOOKUP($Y$2,'Kriter Ağırlık'!$A$1:$B$8,2,1))*X7*E7 -> 35 | Z7: =(TELEF!$I$10*VLOOKUP($Z$2,'Kriter Ağırlık'!$A$1:$B$8,2,1))*X7*E7 -> 15 | AA7: =J7+L7+N7+P7+W7+Y7+Z7 -> 78 | AB7: 2 | AC7: =VLOOKUP(AB7,'Kriter Ağırlık'!$A$12:$C$17,3,0) -> 0 | AD7: 1 | AE7: =VLOOKUP(AD7,'Kriter Ağırlık'!$E$12:$G$24,3,0) -> 1 | AF7: =AA7*AC7*AE7 -> 0 | AG7: =VLOOKUP(A7,'Çalışan Listesi'!A:G,6,0) -> GRUP LİDERİ
A8: 52 | B8: YAVUZ YILMAM | C8: 35962 | D8: =IF($AI$2-C8>=90,90,$AI$2-C8) -> 90 | E8: =D8/90 -> 1 | F8: RİNG BOBİN | G8: Ring Bobin Setup Operatörü | H8: =VLOOKUP(A8,'Çalışan Listesi'!A:G,7,0) -> 3.KADEME | I8: =IFERROR(VLOOKUP(A8,'Kaizen Listesi'!A:H,8,0),0) -> 0 | J8: =I8*VLOOKUP($I$2,'Kriter Ağırlık'!$A$1:$B$8,2,0) -> 0 | K8: =IFERROR(VLOOKUP(A8,'Hata Kartı '!A:H,8,0),0) -> 0 | L8: =K8*(VLOOKUP($K$2,'Kriter Ağırlık'!$A$1:$B$8,2,0)) -> 0 | M8: =IFERROR(VLOOKUP(F8,'5S'!$B$8:$E$19,4,0),0) -> 1 | N8: =VLOOKUP(M8,'5S'!$G$8:$I$14,3,1)*VLOOKUP($M$2,'Kriter Ağırlık'!$A$1:$B$8,2,0)*E8*X8 -> 8 | O8: =IFERROR(VLOOKUP(A8,Devamsızlıklar!A:K,10,0),0) -> 0 | P8: =VLOOKUP(O8,Aralıklar!$A$2:$C$5,3,1)*VLOOKUP($O$2,'Kriter Ağırlık'!$A$1:$B$8,2,0)*E8*X8 -> 10 | Q8: =IFERROR(VLOOKUP(A8,Devamsızlıklar!A:K,8,0),0) -> 0 | R8: =VLOOKUP(Q8,Aralıklar!$E$2:$G$5,3,1) -> 1 | S8: =IFERROR(VLOOKUP(A8,Devamsızlıklar!A:K,9,0),0) -> 0 | T8: =VLOOKUP(S8,Aralıklar!$I$2:$K$6,3,1) -> 50 | U8: =IFERROR(VLOOKUP(A8,Devamsızlıklar!A:K,11,0),0) -> 0 | V8: =VLOOKUP(U8,Aralıklar!$M$2:$O$6,3,1) -> 50 | W8: =IF(X8=0,0,(T8+V8)*R8*VLOOKUP($W$2,'Kriter Ağırlık'!$A$1:$B$8,2,1)*E8) -> 10 | X8: =IFERROR(VLOOKUP(A8,Devamsızlıklar!A:M,13,0),1) -> 1 | Y8: =(OEE!$K$6*VLOOKUP($Y$2,'Kriter Ağırlık'!$A$1:$B$8,2,1))*X8*E8 -> 35 | Z8: =(TELEF!$I$10*VLOOKUP($Z$2,'Kriter Ağırlık'!$A$1:$B$8,2,1))*X8*E8 -> 15 | AA8: =J8+L8+N8+P8+W8+Y8+Z8 -> 78 | AB8: 5 | AC8: =VLOOKUP(AB8,'Kriter Ağırlık'!$A$12:$C$17,3,0) -> 18.5 | AD8: 3 | AE8: =VLOOKUP(AD8,'Kriter Ağırlık'!$E$12:$G$24,3,0) -> 1.15 | AF8: =AA8*AC8*AE8 -> 1659.45 | AG8: =VLOOKUP(A8,'Çalışan Listesi'!A:G,6,0) -> OPERATÖR
A9: 57 | B9: MUHAMMED GÜMÜŞ | C9: 35485 | D9: =IF($AI$2-C9>=90,90,$AI$2-C9) -> 90 | E9: =D9/90 -> 1 | F9: MEKANİK | G9: Mekanik Bakım Takım Lideri Yardımcısı | H9: =VLOOKUP(A9,'Çalışan Listesi'!A:G,7,0) -> 3.KADEME | I9: =IFERROR(VLOOKUP(A9,'Kaizen Listesi'!A:H,8,0),0) -> 0 | J9: =I9*VLOOKUP($I$2,'Kriter Ağırlık'!$A$1:$B$8,2,0) -> 0 | K9: =IFERROR(VLOOKUP(A9,'Hata Kartı '!A:H,8,0),0) -> 66.666667 | L9: =K9*(VLOOKUP($K$2,'Kriter Ağırlık'!$A$1:$B$8,2,0)) -> 6.6666667 | M9: =IFERROR(VLOOKUP(F9,'5S'!$B$8:$E$19,4,0),0) -> 1 | N9: =VLOOKUP(M9,'5S'!$G$8:$I$14,3,1)*VLOOKUP($M$2,'Kriter Ağırlık'!$A$1:$B$8,2,0)*E9*X9 -> 8 | O9: =IFERROR(VLOOKUP(A9,Devamsızlıklar!A:K,10,0),0) -> 0 | P9: =VLOOKUP(O9,Aralıklar!$A$2:$C$5,3,1)*VLOOKUP($O$2,'Kriter Ağırlık'!$A$1:$B$8,2,0)*E9*X9 -> 10 | Q9: =IFERROR(VLOOKUP(A9,Devamsızlıklar!A:K,8,0),0) -> 0 | R9: =VLOOKUP(Q9,Aralıklar!$E$2:$G$5,3,1) -> 1 | S9: =IFERROR(VLOOKUP(A9,Devamsızlıklar!A:K,9,0),0) -> 0 | T9: =VLOOKUP(S9,Aralıklar!$I$2:$K$6,3,1) -> 50 | U9: =IFERROR(VLOOKUP(A9,Devamsızlıklar!A:K,11,0),0) -> 0 | V9: =VLOOKUP(U9,Aralıklar!$M$2:$O$6,3,1) -> 50 | W9: =IF(X9=0,0,(T9+V9)*R9*VLOOKUP($W$2,'Kriter Ağırlık'!$A$1:$B$8,2,1)*E9) -> 10 | X9: =IFERROR(VLOOKUP(A9,Devamsızlıklar!A:M,13,0),1) -> 1 | Y9: =(OEE!$K$6*VLOOKUP($Y$2,'Kriter Ağırlık'!$A$1:$B$8,2,1))*X9*E9 -> 35 | Z9: =(TELEF!$I$10*VLOOKUP($Z$2,'Kriter Ağırlık'!$A$1:$B$8,2,1))*X9*E9 -> 15 | AA9: =J9+L9+N9+P9+W9+Y9+Z9 -> 84.666667 | AB9: 4 | AC9: =VLOOKUP(AB9,'Kriter Ağırlık'!$A$12:$C$17,3,0) -> 13.5 | AD9: 1 | AE9: =VLOOKUP(AD9,'Kriter Ağırlık'!$E$12:$G$24,3,0) -> 1 | AF9: =AA9*AC9*AE9 -> 1143 | AG9: =VLOOKUP(A9,'Çalışan Listesi'!A:G,6,0) -> TAKIM LİDERİ YARDIMCISI
A10: 64 | B10: MAHMUT MENTEŞ | C10: 34506 | D10: =IF($AI$2-C10>=90,90,$AI$2-C10) -> 90 | E10: =D10/90 -> 1 | F10: ENERJİ | G10: Bakım Ekip Lideri | H10: =VLOOKUP(A10,'Çalışan Listesi'!A:G,7,0) -> EKİP LİDERİ | I10: =IFERROR(VLOOKUP(A10,'Kaizen Listesi'!A:H,8,0),0) -> 0 | J10: =I10*VLOOKUP($I$2,'Kriter Ağırlık'!$A$1:$B$8,2,0) -> 0 | K10: =IFERROR(VLOOKUP(A10,'Hata Kartı '!A:H,8,0),0) -> 16.666667 | L10: =K10*(VLOOKUP($K$2,'Kriter Ağırlık'!$A$1:$B$8,2,0)) -> 1.6666667 | M10: =IFERROR(VLOOKUP(F10,'5S'!$B$8:$E$19,4,0),0) -> 1 | N10: =VLOOKUP(M10,'5S'!$G$8:$I$14,3,1)*VLOOKUP($M$2,'Kriter Ağırlık'!$A$1:$B$8,2,0)*E10*X10 -> 7.5555556 | O10: =IFERROR(VLOOKUP(A10,Devamsızlıklar!A:K,10,0),0) -> 0 | P10: =VLOOKUP(O10,Aralıklar!$A$2:$C$5,3,1)*VLOOKUP($O$2,'Kriter Ağırlık'!$A$1:$B$8,2,0)*E10*X10 -> 9.4444444 | Q10: =IFERROR(VLOOKUP(A10,Devamsızlıklar!A:K,8,0),0) -> 0 | R10: =VLOOKUP(Q10,Aralıklar!$E$2:$G$5,3,1) -> 1 | S10: =IFERROR(VLOOKUP(A10,Devamsızlıklar!A:K,9,0),0) -> 5 | T10: =VLOOKUP(S10,Aralıklar!$I$2:$K$6,3,1) -> 25 | U10: =IFERROR(VLOOKUP(A10,Devamsızlıklar!A:K,11,0),0) -> 0 | V10: =VLOOKUP(U10,Aralıklar!$M$2:$O$6,3,1) -> 50 | W10: =IF(X10=0,0,(T10+V10)*R10*VLOOKUP($W$2,'Kriter Ağırlık'!$A$1:$B$8,2,1)*E10) -> 7.5 | X10: =IFERROR(VLOOKUP(A10,Devamsızlıklar!A:M,13,0),1) -> 0.94444444 | Y10: =(OEE!$K$6*VLOOKUP($Y$2,'Kriter Ağırlık'!$A$1:$B$8,2,1))*X10*E10 -> 33.055556 | Z10: =(TELEF!$I$10*VLOOKUP($Z$2,'Kriter Ağırlık'!$A$1:$B$8,2,1))*X10*E10 -> 14.166667 | AA10: =J10+L10+N10+P10+W10+Y10+Z10 -> 73.388889 | AB10: 1 | AC10: =VLOOKUP(AB10,'Kriter Ağırlık'!$A$12:$C$17,3,0) -> 0 | AD10: 1 | AE10: =VLOOKUP(AD10,'Kriter Ağırlık'!$E$12:$G$24,3,0) -> 1 | AF10: =AA10*AC10*AE10 -> 0 | AG10: =VLOOKUP(A10,'Çalışan Listesi'!A:G,6,0) -> ŞEF LİDER
A11: 72 | B11: MEHMET KÖSE | C11: 36074 | D11: =IF($AI$2-C11>=90,90,$AI$2-C11) -> 90 | E11: =D11/90 -> 1 | F11: MAKİNE TEMİZLİK | G11: Makine Temizlik Takım Lideri | H11: =VLOOKUP(A11,'Çalışan Listesi'!A:G,7,0) -> 4.KADEME | I11: =IFERROR(VLOOKUP(A11,'Kaizen Listesi'!A:H,8,0),0) -> 0 | J11: =I11*VLOOKUP($I$2,'Kriter Ağırlık'!$A$1:$B$8,2,0) -> 0 | K11: =IFERROR(VLOOKUP(A11,'Hata Kartı '!A:H,8,0),0) -> 100 | L11: =K11*(VLOOKUP($K$2,'Kriter Ağırlık'!$A$1:$B$8,2,0)) -> 10 | M11: =IFERROR(VLOOKUP(F11,'5S'!$B$8:$E$19,4,0),0) -> 1 | N11: =VLOOKUP(M11,'5S'!$G$8:$I$14,3,1)*VLOOKUP($M$2,'Kriter Ağırlık'!$A$1:$B$8,2,0)*E11*X11 -> 8 | O11: =IFERROR(VLOOKUP(A11,Devamsızlıklar!A:K,10,0),0) -> 0 | P11: =VLOOKUP(O11,Aralıklar!$A$2:$C$5,3,1)*VLOOKUP($O$2,'Kriter Ağırlık'!$A$1:$B$8,2,0)*E11*X11 -> 10 | Q11: =IFERROR(VLOOKUP(A11,Devamsızlıklar!A:K,8,0),0) -> 0 | R11: =VLOOKUP(Q11,Aralıklar!$E$2:$G$5,3,1) -> 1 | S11: =IFERROR(VLOOKUP(A11,Devamsızlıklar!A:K,9,0),0) -> 0 | T11: =VLOOKUP(S11,Aralıklar!$I$2:$K$6,3,1) -> 50 | U11: =IFERROR(VLOOKUP(A11,Devamsızlıklar!A:K,11,0),0) -> 0 | V11: =VLOOKUP(U11,Aralıklar!$M$2:$O$6,3,1) -> 50 | W11: =IF(X11=0,0,(T11+V11)*R11*VLOOKUP($W$2,'Kriter Ağırlık'!$A$1:$B$8,2,1)*E11) -> 10 | X11: =IFERROR(VLOOKUP(A11,Devamsızlıklar!A:M,13,0),1) -> 1 | Y11: =(OEE!$K$6*VLOOKUP($Y$2,'Kriter Ağırlık'!$A$1:$B$8,2,1))*X11*E11 -> 35 | Z11: =(TELEF!$I$10*VLOOKUP($Z$2,'Kriter Ağırlık'!$A$1:$B$8,2,1))*X11*E11 -> 15 | AA11: =J11+L11+N11+P11+W11+Y11+Z11 -> 88 | AB11: 3 | AC11: =VLOOKUP(AB11,'Kriter Ağırlık'!$A$12:$C$17,3,0) -> 0 | AD11: 2 | AE11: =VLOOKUP(AD11,'Kriter Ağırlık'!$E$12:$G$24,3,0) -> 1.232 | AF11: =AA11*AC11*AE11 -> 0 | AG11: =VLOOKUP(A11,'Çalışan Listesi'!A:G,6,0) -> TAKIM LİDERİ
A12: 73 | B12: VEYSAL DURMUŞ | C12: 34745 | D12: =IF($AI$2-C12>=90,90,$AI$2-C12) -> 90 | E12: =D12/90 -> 1 | F12: RİNG BOBİN | G12: Ring Bobin Setup Operatörü | H12: =VLOOKUP(A12,'Çalışan Listesi'!A:G,7,0) -> 3.KADEME | I12: =IFERROR(VLOOKUP(A12,'Kaizen Listesi'!A:H,8,0),0) -> 0 | J12: =I12*VLOOKUP($I$2,'Kriter Ağırlık'!$A$1:$B$8,2,0) -> 0 | K12: =IFERROR(VLOOKUP(A12,'Hata Kartı '!A:H,8,0),0) -> 0 | L12: =K12*(VLOOKUP($K$2,'Kriter Ağırlık'!$A$1:$B$8,2,0)) -> 0 | M12: =IFERROR(VLOOKUP(F12,'5S'!$B$8:$E$19,4,0),0) -> 1 | N12: =VLOOKUP(M12,'5S'!$G$8:$I$14,3,1)*VLOOKUP($M$2,'Kriter Ağırlık'!$A$1:$B$8,2,0)*E12*X12 -> 7.4666667 | O12: =IFERROR(VLOOKUP(A12,Devamsızlıklar!A:K,10,0),0) -> 0 | P12: =VLOOKUP(O12,Aralıklar!$A$2:$C$5,3,1)*VLOOKUP($O$2,'Kriter Ağırlık'!$A$1:$B$8,2,0)*E12*X12 -> 9.3333333 | Q12: =IFERROR(VLOOKUP(A12,Devamsızlıklar!A:K,8,0),0) -> 0 | R12: =VLOOKUP(Q12,Aralıklar!$E$2:$G$5,3,1) -> 1 | S12: =IFERROR(VLOOKUP(A12,Devamsızlıklar!A:K,9,0),0) -> 0 | T12: =VLOOKUP(S12,Aralıklar!$I$2:$K$6,3,1) -> 50 | U12: =IFERROR(VLOOKUP(A12,Devamsızlıklar!A:K,11,0),0) -> 0 | V12: =VLOOKUP(U12,Aralıklar!$M$2:$O$6,3,1) -> 50 | W12: =IF(X12=0,0,(T12+V12)*R12*VLOOKUP($W$2,'Kriter Ağırlık'!$A$1:$B$8,2,1)*E12) -> 10 | X12: =IFERROR(VLOOKUP(A12,Devamsızlıklar!A:M,13,0),1) -> 0.93333333 | Y12: =(OEE!$K$6*VLOOKUP($Y$2,'Kriter Ağırlık'!$A$1:$B$8,2,1))*X12*E12 -> 32.666667 | Z12: =(TELEF!$I$10*VLOOKUP($Z$2,'Kriter Ağırlık'!$A$1:$B$8,2,1))*X12*E12 -> 14 | AA12: =J12+L12+N12+P12+W12+Y12+Z12 -> 73.466667 | AB12: 5 | AC12: =VLOOKUP(AB12,'Kriter Ağırlık'!$A$12:$C$17,3,0) -> 18.5 | AD12: 3 | AE12: =VLOOKUP(AD12,'Kriter Ağırlık'!$E$12:$G$24,3,0) -> 1.15 | AF12: =AA12*AC12*AE12 -> 1563.0033 | AG12: =VLOOKUP(A12,'Çalışan Listesi'!A:G,6,0) -> OPERATÖR
A13: 74 | B13: AKIN ÖZTÜRK | C13: 34771 | D13: =IF($AI$2-C13>=90,90,$AI$2-C13) -> 90 | E13: =D13/90 -> 1 | F13: MEKANİK | G13: Bakım Ekip Lideri | H13: =VLOOKUP(A13,'Çalışan Listesi'!A:G,7,0) -> EKİP LİDERİ | I13: =IFERROR(VLOOKUP(A13,'Kaizen Listesi'!A:H,8,0),0) -> 0 | J13: =I13*VLOOKUP($I$2,'Kriter Ağırlık'!$A$1:$B$8,2,0) -> 0 | K13: =IFERROR(VLOOKUP(A13,'Hata Kartı '!A:H,8,0),0) -> 0 | L13: =K13*(VLOOKUP($K$2,'Kriter Ağırlık'!$A$1:$B$8,2,0)) -> 0 | M13: =IFERROR(VLOOKUP(F13,'5S'!$B$8:$E$19,4,0),0) -> 1 | N13: =VLOOKUP(M13,'5S'!$G$8:$I$14,3,1)*VLOOKUP($M$2,'Kriter Ağırlık'!$A$1:$B$8,2,0)*E13*X13 -> 8 | O13: =IFERROR(VLOOKUP(A13,Devamsızlıklar!A:K,10,0),0) -> 0 | P13: =VLOOKUP(O13,Aralıklar!$A$2:$C$5,3,1)*VLOOKUP($O$2,'Kriter Ağırlık'!$A$1:$B$8,2,0)*E13*X13 -> 10 | Q13: =IFERROR(VLOOKUP(A13,Devamsızlıklar!A:K,8,0),0) -> 0 | R13: =VLOOKUP(Q13,Aralıklar!$E$2:$G$5,3,1) -> 1 | S13: =IFERROR(VLOOKUP(A13,Devamsızlıklar!A:K,9,0),0) -> 0 | T13: =VLOOKUP(S13,Aralıklar!$I$2:$K$6,3,1) -> 50 | U13: =IFERROR(VLOOKUP(A13,Devamsızlıklar!A:K,11,0),0) -> 0 | V13: =VLOOKUP(U13,Aralıklar!$M$2:$O$6,3,1) -> 50 | W13: =IF(X13=0,0,(T13+V13)*R13*VLOOKUP($W$2,'Kriter Ağırlık'!$A$1:$B$8,2,1)*E13) -> 10 | X13: =IFERROR(VLOOKUP(A13,Devamsızlıklar!A:M,13,0),1) -> 1 | Y13: =(OEE!$K$6*VLOOKUP($Y$2,'Kriter Ağırlık'!$A$1:$B$8,2,1))*X13*E13 -> 35 | Z13: =(TELEF!$I$10*VLOOKUP($Z$2,'Kriter Ağırlık'!$A$1:$B$8,2,1))*X13*E13 -> 15 | AA13: =J13+L13+N13+P13+W13+Y13+Z13 -> 78 | AB13: 1 | AC13: =VLOOKUP(AB13,'Kriter Ağırlık'!$A$12:$C$17,3,0) -> 0 | AD13: 1 | AE13: =VLOOKUP(AD13,'Kriter Ağırlık'!$E$12:$G$24,3,0) -> 1 | AF13: =AA13*AC13*AE13 -> 0 | AG13: =VLOOKUP(A13,'Çalışan Listesi'!A:G,6,0) -> ŞEF LİDER
A14: 79 | B14: AHMET YÖRÜK | C14: 34916 | D14: =IF($AI$2-C14>=90,90,$AI$2-C14) -> 90 | E14: =D14/90 -> 1 | F14: İHSARAT | G14: İhsarat Grup Lideri | H14: =VLOOKUP(A14,'Çalışan Listesi'!A:G,7,0) -> SÜPERVİZÖR | I14: =IFERROR(VLOOKUP(A14,'Kaizen Listesi'!A:H,8,0),0) -> 0 | J14: =I14*VLOOKUP($I$2,'Kriter Ağırlık'!$A$1:$B$8,2,0) -> 0 | K14: =IFERROR(VLOOKUP(A14,'Hata Kartı '!A:H,8,0),0) -> 0 | L14: =K14*(VLOOKUP($K$2,'Kriter Ağırlık'!$A$1:$B$8,2,0)) -> 0 | M14: =IFERROR(VLOOKUP(F14,'5S'!$B$8:$E$19,4,0),0) -> 1 | N14: =VLOOKUP(M14,'5S'!$G$8:$I$14,3,1)*VLOOKUP($M$2,'Kriter Ağırlık'!$A$1:$B$8,2,0)*E14*X14 -> 8 | O14: =IFERROR(VLOOKUP(A14,Devamsızlıklar!A:K,10,0),0) -> 0 | P14: =VLOOKUP(O14,Aralıklar!$A$2:$C$5,3,1)*VLOOKUP($O$2,'Kriter Ağırlık'!$A$1:$B$8,2,0)*E14*X14 -> 10 | Q14: =IFERROR(VLOOKUP(A14,Devamsızlıklar!A:K,8,0),0) -> 0 | R14: =VLOOKUP(Q14,Aralıklar!$E$2:$G$5,3,1) -> 1 | S14: =IFERROR(VLOOKUP(A14,Devamsızlıklar!A:K,9,0),0) -> 0 | T14: =VLOOKUP(S14,Aralıklar!$I$2:$K$6,3,1) -> 50 | U14: =IFERROR(VLOOKUP(A14,Devamsızlıklar!A:K,11,0),0) -> 0 | V14: =VLOOKUP(U14,Aralıklar!$M$2:$O$6,3,1) -> 50 | W14: =IF(X14=0,0,(T14+V14)*R14*VLOOKUP($W$2,'Kriter Ağırlık'!$A$1:$B$8,2,1)*E14) -> 10 | X14: =IFERROR(VLOOKUP(A14,Devamsızlıklar!A:M,13,0),1) -> 1 | Y14: =(OEE!$K$6*VLOOKUP($Y$2,'Kriter Ağırlık'!$A$1:$B$8,2,1))*X14*E14 -> 35 | Z14: =(TELEF!$I$10*VLOOKUP($Z$2,'Kriter Ağırlık'!$A$1:$B$8,2,1))*X14*E14 -> 15 | AA14: =J14+L14+N14+P14+W14+Y14+Z14 -> 78 | AB14: 2 | AC14: =VLOOKUP(AB14,'Kriter Ağırlık'!$A$12:$C$17,3,0) -> 0 | AD14: 1 | AE14: =VLOOKUP(AD14,'Kriter Ağırlık'!$E$12:$G$24,3,0) -> 1 | AF14: =AA14*AC14*AE14 -> 0 | AG14: =VLOOKUP(A14,'Çalışan Listesi'!A:G,6,0) -> GRUP LİDERİ
... A22: 108 | B22: MUSTAFA EMREM | C22: 35445 | D22: =IF($AI$2-C22>=90,90,$AI$2-C22) -> 90 | E22: =D22/90 -> 1 | F22: MEKANİK | G22: Mekanik Bakım Takım Lideri | H22: =VLOOKUP(A22,'Çalışan Listesi'!A:G,7,0) -> 3.KADEME | I22: =IFERROR(VLOOKUP(A22,'Kaizen Listesi'!A:H,8,0),0) -> 33.333333 | J22: =I22*VLOOKUP($I$2,'Kriter Ağırlık'!$A$1:$B$8,2,0) -> 4 | K22: =IFERROR(VLOOKUP(A22,'Hata Kartı '!A:H,8,0),0) -> 0 | L22: =K22*(VLOOKUP($K$2,'Kriter Ağırlık'!$A$1:$B$8,2,0)) -> 0 | M22: =IFERROR(VLOOKUP(F22,'5S'!$B$8:$E$19,4,0),0) -> 1 | N22: =VLOOKUP(M22,'5S'!$G$8:$I$14,3,1)*VLOOKUP($M$2,'Kriter Ağırlık'!$A$1:$B$8,2,0)*E22*X22 -> 7.4666667 | O22: =IFERROR(VLOOKUP(A22,Devamsızlıklar!A:K,10,0),0) -> 0 | P22: =VLOOKUP(O22,Aralıklar!$A$2:$C$5,3,1)*VLOOKUP($O$2,'Kriter Ağırlık'!$A$1:$B$8,2,0)*E22*X22 -> 9.3333333 | Q22: =IFERROR(VLOOKUP(A22,Devamsızlıklar!A:K,8,0),0) -> 0 | R22: =VLOOKUP(Q22,Aralıklar!$E$2:$G$5,3,1) -> 1 | S22: =IFERROR(VLOOKUP(A22,Devamsızlıklar!A:K,9,0),0) -> 0 | T22: =VLOOKUP(S22,Aralıklar!$I$2:$K$6,3,1) -> 50 | U22: =IFERROR(VLOOKUP(A22,Devamsızlıklar!A:K,11,0),0) -> 0 | V22: =VLOOKUP(U22,Aralıklar!$M$2:$O$6,3,1) -> 50 | W22: =IF(X22=0,0,(T22+V22)*R22*VLOOKUP($W$2,'Kriter Ağırlık'!$A$1:$B$8,2,1)*E22) -> 10 | X22: =IFERROR(VLOOKUP(A22,Devamsızlıklar!A:M,13,0),1) -> 0.93333333 | Y22: =(OEE!$K$6*VLOOKUP($Y$2,'Kriter Ağırlık'!$A$1:$B$8,2,1))*X22*E22 -> 32.666667 | Z22: =(TELEF!$I$10*VLOOKUP($Z$2,'Kriter Ağırlık'!$A$1:$B$8,2,1))*X22*E22 -> 14 | AA22: =J22+L22+N22+P22+W22+Y22+Z22 -> 77.466667 | AB22: 3 | AC22: =VLOOKUP(AB22,'Kriter Ağırlık'!$A$12:$C$17,3,0) -> 0 | AD22: 10 | AE22: =VLOOKUP(AD22,'Kriter Ağırlık'!$E$12:$G$24,3,0) -> 1.378 | AF22: =AA22*AC22*AE22 -> 0 | AG22: =VLOOKUP(A22,'Çalışan Listesi'!A:G,6,0) -> TAKIM LİDERİ
A23: 109 | B23: RECAİ ELİUZ | C23: 40805 | D23: 60 | E23: =D23/90 -> 0.66666667 | F23: RİNG BOBİN | G23: Ring Bobin Setup Takım Lideri Yardımcısı | H23: =VLOOKUP(A23,'Çalışan Listesi'!A:G,7,0) -> 3.KADEME | I23: =IFERROR(VLOOKUP(A23,'Kaizen Listesi'!A:H,8,0),0) -> 50 | J23: =I23*VLOOKUP($I$2,'Kriter Ağırlık'!$A$1:$B$8,2,0) -> 6 | K23: =IFERROR(VLOOKUP(A23,'Hata Kartı '!A:H,8,0),0) -> 50 | L23: =K23*(VLOOKUP($K$2,'Kriter Ağırlık'!$A$1:$B$8,2,0)) -> 5 | M23: =IFERROR(VLOOKUP(F23,'5S'!$B$8:$E$19,4,0),0) -> 1 | N23: =VLOOKUP(M23,'5S'!$G$8:$I$14,3,1)*VLOOKUP($M$2,'Kriter Ağırlık'!$A$1:$B$8,2,0)*E23*X23 -> 5.3333333 | O23: =IFERROR(VLOOKUP(A23,Devamsızlıklar!A:K,10,0),0) -> 0 | P23: =VLOOKUP(O23,Aralıklar!$A$2:$C$5,3,1)*VLOOKUP($O$2,'Kriter Ağırlık'!$A$1:$B$8,2,0)*E23*X23 -> 6.6666667 | Q23: =IFERROR(VLOOKUP(A23,Devamsızlıklar!A:K,8,0),0) -> 0 | R23: =VLOOKUP(Q23,Aralıklar!$E$2:$G$5,3,1) -> 1 | S23: =IFERROR(VLOOKUP(A23,Devamsızlıklar!A:K,9,0),0) -> 0 | T23: =VLOOKUP(S23,Aralıklar!$I$2:$K$6,3,1) -> 50 | U23: =IFERROR(VLOOKUP(A23,Devamsızlıklar!A:K,11,0),0) -> 0 | V23: =VLOOKUP(U23,Aralıklar!$M$2:$O$6,3,1) -> 50 | W23: =IF(X23=0,0,(T23+V23)*R23*VLOOKUP($W$2,'Kriter Ağırlık'!$A$1:$B$8,2,1)*E23) -> 6.6666667 | X23: =IFERROR(VLOOKUP(A23,Devamsızlıklar!A:M,13,0),1) -> 1 | Y23: =(OEE!$K$6*VLOOKUP($Y$2,'Kriter Ağırlık'!$A$1:$B$8,2,1))*X23*E23 -> 23.333333 | Z23: =(TELEF!$I$10*VLOOKUP($Z$2,'Kriter Ağırlık'!$A$1:$B$8,2,1))*X23*E23 -> 10 | AA23: =J23+L23+N23+P23+W23+Y23+Z23 -> 63 | AB23: 5 | AC23: =VLOOKUP(AB23,'Kriter Ağırlık'!$A$12:$C$17,3,0) -> 18.5 | AD23: 3 | AE23: =VLOOKUP(AD23,'Kriter Ağırlık'!$E$12:$G$24,3,0) -> 1.15 | AF23: =AA23*AC23*AE23 -> 1340.325 | AG23: =VLOOKUP(A23,'Çalışan Listesi'!A:G,6,0) -> TAKIM LİDERİ YARDIMCISI
A24: 112 | B24: ALİ DİNGER | C24: 35555 | D24: =IF($AI$2-C24>=90,90,$AI$2-C24) -> 90 | E24: =D24/90 -> 1 | F24: ENERJİ | G24: Elektrik Bakım Takım Lideri | H24: =VLOOKUP(A24,'Çalışan Listesi'!A:G,7,0) -> 4.KADEME | I24: =IFERROR(VLOOKUP(A24,'Kaizen Listesi'!A:H,8,0),0) -> 0 | J24: =I24*VLOOKUP($I$2,'Kriter Ağırlık'!$A$1:$B$8,2,0) -> 0 | K24: =IFERROR(VLOOKUP(A24,'Hata Kartı '!A:H,8,0),0) -> 0 | L24: =K24*(VLOOKUP($K$2,'Kriter Ağırlık'!$A$1:$B$8,2,0)) -> 0 | M24: =IFERROR(VLOOKUP(F24,'5S'!$B$8:$E$19,4,0),0) -> 1 | N24: =VLOOKUP(M24,'5S'!$G$8:$I$14,3,1)*VLOOKUP($M$2,'Kriter Ağırlık'!$A$1:$B$8,2,0)*E24*X24 -> 7.3777778 | O24: =IFERROR(VLOOKUP(A24,Devamsızlıklar!A:K,10,0),0) -> 0 | P24: =VLOOKUP(O24,Aralıklar!$A$2:$C$5,3,1)*VLOOKUP($O$2,'Kriter Ağırlık'!$A$1:$B$8,2,0)*E24*X24 -> 9.2222222 | Q24: =IFERROR(VLOOKUP(A24,Devamsızlıklar!A:K,8,0),0) -> 0 | R24: =VLOOKUP(Q24,Aralıklar!$E$2:$G$5,3,1) -> 1 | S24: =IFERROR(VLOOKUP(A24,Devamsızlıklar!A:K,9,0),0) -> 0 | T24: =VLOOKUP(S24,Aralıklar!$I$2:$K$6,3,1) -> 50 | U24: =IFERROR(VLOOKUP(A24,Devamsızlıklar!A:K,11,0),0) -> 0 | V24: =VLOOKUP(U24,Aralıklar!$M$2:$O$6,3,1) -> 50 | W24: =IF(X24=0,0,(T24+V24)*R24*VLOOKUP($W$2,'Kriter Ağırlık'!$A$1:$B$8,2,1)*E24) -> 10 | X24: =IFERROR(VLOOKUP(A24,Devamsızlıklar!A:M,13,0),1) -> 0.92222222 | Y24: =(OEE!$K$6*VLOOKUP($Y$2,'Kriter Ağırlık'!$A$1:$B$8,2,1))*X24*E24 -> 32.277778 | Z24: =(TELEF!$I$10*VLOOKUP($Z$2,'Kriter Ağırlık'!$A$1:$B$8,2,1))*X24*E24 -> 13.833333 | AA24: =J24+L24+N24+P24+W24+Y24+Z24 -> 72.711111 | AB24: 3 | AC24: =VLOOKUP(AB24,'Kriter Ağırlık'!$A$12:$C$17,3,0) -> 0 | AD24: 6 | AE24: =VLOOKUP(AD24,'Kriter Ağırlık'!$E$12:$G$24,3,0) -> 1.287 | AF24: =AA24*AC24*AE24 -> 0 | AG24: =VLOOKUP(A24,'Çalışan Listesi'!A:G,6,0) -> TAKIM LİDERİ
A25: 113 | B25: MEHMET KÖK | C25: 35584 | D25: =IF($AI$2-C25>=90,90,$AI$2-C25) -> 90 | E25: =D25/90 -> 1 | F25: KALİTE | G25: Rektefiye Operatörü | H25: =VLOOKUP(A25,'Çalışan Listesi'!A:G,7,0) -> KADEME YOK | I25: =IFERROR(VLOOKUP(A25,'Kaizen Listesi'!A:H,8,0),0) -> 0 | J25: =I25*VLOOKUP($I$2,'Kriter Ağırlık'!$A$1:$B$8,2,0) -> 0 | K25: =IFERROR(VLOOKUP(A25,'Hata Kartı '!A:H,8,0),0) -> 66.666667 | L25: =K25*(VLOOKUP($K$2,'Kriter Ağırlık'!$A$1:$B$8,2,0)) -> 6.6666667 | M25: =IFERROR(VLOOKUP(F25,'5S'!$B$8:$E$19,4,0),0) -> 1 | N25: =VLOOKUP(M25,'5S'!$G$8:$I$14,3,1)*VLOOKUP($M$2,'Kriter Ağırlık'!$A$1:$B$8,2,0)*E25*X25 -> 8 | O25: =IFERROR(VLOOKUP(A25,Devamsızlıklar!A:K,10,0),0) -> 0 | P25: =VLOOKUP(O25,Aralıklar!$A$2:$C$5,3,1)*VLOOKUP($O$2,'Kriter Ağırlık'!$A$1:$B$8,2,0)*E25*X25 -> 10 | Q25: =IFERROR(VLOOKUP(A25,Devamsızlıklar!A:K,8,0),0) -> 0 | R25: =VLOOKUP(Q25,Aralıklar!$E$2:$G$5,3,1) -> 1 | S25: =IFERROR(VLOOKUP(A25,Devamsızlıklar!A:K,9,0),0) -> 0 | T25: =VLOOKUP(S25,Aralıklar!$I$2:$K$6,3,1) -> 50 | U25: =IFERROR(VLOOKUP(A25,Devamsızlıklar!A:K,11,0),0) -> 0 | V25: =VLOOKUP(U25,Aralıklar!$M$2:$O$6,3,1) -> 50 | W25: =IF(X25=0,0,(T25+V25)*R25*VLOOKUP($W$2,'Kriter Ağırlık'!$A$1:$B$8,2,1)*E25) -> 10 | X25: =IFERROR(VLOOKUP(A25,Devamsızlıklar!A:M,13,0),1) -> 1 | Y25: =(OEE!$K$6*VLOOKUP($Y$2,'Kriter Ağırlık'!$A$1:$B$8,2,1))*X25*E25 -> 35 | Z25: =(TELEF!$I$10*VLOOKUP($Z$2,'Kriter Ağırlık'!$A$1:$B$8,2,1))*X25*E25 -> 15 | AA25: =J25+L25+N25+P25+W25+Y25+Z25 -> 84.666667 | AB25: 5 | AC25: =VLOOKUP(AB25,'Kriter Ağırlık'!$A$12:$C$17,3,0) -> 18.5 | AD25: 10 | AE25: =VLOOKUP(AD25,'Kriter Ağırlık'!$E$12:$G$24,3,0) -> 1.378 | AF25: =AA25*AC25*AE25 -> 2158.4073 | AG25: =VLOOKUP(A25,'Çalışan Listesi'!A:G,6,0) -> OPERATÖR
A26: 120 | B26: ÜMİT ALTINTAŞ | C26: 35654 | D26: =IF($AI$2-C26>=90,90,$AI$2-C26) -> 90 | E26: =D26/90 -> 1 | F26: RİNG BOBİN | G26: Ring Bobin Setup Operatörü | H26: =VLOOKUP(A26,'Çalışan Listesi'!A:G,7,0) -> 3.KADEME | I26: =IFERROR(VLOOKUP(A26,'Kaizen Listesi'!A:H,8,0),0) -> 0 | J26: =I26*VLOOKUP($I$2,'Kriter Ağırlık'!$A$1:$B$8,2,0) -> 0 | K26: =IFERROR(VLOOKUP(A26,'Hata Kartı '!A:H,8,0),0) -> 33.333333 | L26: =K26*(VLOOKUP($K$2,'Kriter Ağırlık'!$A$1:$B$8,2,0)) -> 3.3333333 | M26: =IFERROR(VLOOKUP(F26,'5S'!$B$8:$E$19,4,0),0) -> 1 | N26: =VLOOKUP(M26,'5S'!$G$8:$I$14,3,1)*VLOOKUP($M$2,'Kriter Ağırlık'!$A$1:$B$8,2,0)*E26*X26 -> 8 | O26: =IFERROR(VLOOKUP(A26,Devamsızlıklar!A:K,10,0),0) -> 0 | P26: =VLOOKUP(O26,Aralıklar!$A$2:$C$5,3,1)*VLOOKUP($O$2,'Kriter Ağırlık'!$A$1:$B$8,2,0)*E26*X26 -> 10 | Q26: =IFERROR(VLOOKUP(A26,Devamsızlıklar!A:K,8,0),0) -> 0 | R26: =VLOOKUP(Q26,Aralıklar!$E$2:$G$5,3,1) -> 1 | S26: =IFERROR(VLOOKUP(A26,Devamsızlıklar!A:K,9,0),0) -> 0 | T26: =VLOOKUP(S26,Aralıklar!$I$2:$K$6,3,1) -> 50 | U26: =IFERROR(VLOOKUP(A26,Devamsızlıklar!A:K,11,0),0) -> 0 | V26: =VLOOKUP(U26,Aralıklar!$M$2:$O$6,3,1) -> 50 | W26: =IF(X26=0,0,(T26+V26)*R26*VLOOKUP($W$2,'Kriter Ağırlık'!$A$1:$B$8,2,1)*E26) -> 10 | X26: =IFERROR(VLOOKUP(A26,Devamsızlıklar!A:M,13,0),1) -> 1 | Y26: =(OEE!$K$6*VLOOKUP($Y$2,'Kriter Ağırlık'!$A$1:$B$8,2,1))*X26*E26 -> 35 | Z26: =(TELEF!$I$10*VLOOKUP($Z$2,'Kriter Ağırlık'!$A$1:$B$8,2,1))*X26*E26 -> 15 | AA26: =J26+L26+N26+P26+W26+Y26+Z26 -> 81.333333 | AB26: 5 | AC26: =VLOOKUP(AB26,'Kriter Ağırlık'!$A$12:$C$17,3,0) -> 18.5 | AD26: 3 | AE26: =VLOOKUP(AD26,'Kriter Ağırlık'!$E$12:$G$24,3,0) -> 1.15 | AF26: =AA26*AC26*AE26 -> 1730.3667 | AG26: =VLOOKUP(A26,'Çalışan Listesi'!A:G,6,0) -> OPERATÖR
A27: 123 | B27: MUSTAFA BERBEROĞLU | C27: 36817 | D27: =IF($AI$2-C27>=90,90,$AI$2-C27) -> 90 | E27: =D27/90 -> 1 | F27: İHSARAT | G27: İhsarat Grup Lideri | H27: =VLOOKUP(A27,'Çalışan Listesi'!A:G,7,0) -> SÜPERVİZÖR | I27: =IFERROR(VLOOKUP(A27,'Kaizen Listesi'!A:H,8,0),0) -> 66.666667 | J27: =I27*VLOOKUP($I$2,'Kriter Ağırlık'!$A$1:$B$8,2,0) -> 8 | K27: =IFERROR(VLOOKUP(A27,'Hata Kartı '!A:H,8,0),0) -> 33.333333 | L27: =K27*(VLOOKUP($K$2,'Kriter Ağırlık'!$A$1:$B$8,2,0)) -> 3.3333333 | M27: =IFERROR(VLOOKUP(F27,'5S'!$B$8:$E$19,4,0),0) -> 1 | N27: =VLOOKUP(M27,'5S'!$G$8:$I$14,3,1)*VLOOKUP($M$2,'Kriter Ağırlık'!$A$1:$B$8,2,0)*E27*X27 -> 8 | O27: =IFERROR(VLOOKUP(A27,Devamsızlıklar!A:K,10,0),0) -> 0 | P27: =VLOOKUP(O27,Aralıklar!$A$2:$C$5,3,1)*VLOOKUP($O$2,'Kriter Ağırlık'!$A$1:$B$8,2,0)*E27*X27 -> 10 | Q27: =IFERROR(VLOOKUP(A27,Devamsızlıklar!A:K,8,0),0) -> 0 | R27: =VLOOKUP(Q27,Aralıklar!$E$2:$G$5,3,1) -> 1 | S27: =IFERROR(VLOOKUP(A27,Devamsızlıklar!A:K,9,0),0) -> 0 | T27: =VLOOKUP(S27,Aralıklar!$I$2:$K$6,3,1) -> 50 | U27: =IFERROR(VLOOKUP(A27,Devamsızlıklar!A:K,11,0),0) -> 0 | V27: =VLOOKUP(U27,Aralıklar!$M$2:$O$6,3,1) -> 50 | W27: =IF(X27=0,0,(T27+V27)*R27*VLOOKUP($W$2,'Kriter Ağırlık'!$A$1:$B$8,2,1)*E27) -> 10 | X27: =IFERROR(VLOOKUP(A27,Devamsızlıklar!A:M,13,0),1) -> 1 | Y27: =(OEE!$K$6*VLOOKUP($Y$2,'Kriter Ağırlık'!$A$1:$B$8,2,1))*X27*E27 -> 35 | Z27: =(TELEF!$I$10*VLOOKUP($Z$2,'Kriter Ağırlık'!$A$1:$B$8,2,1))*X27*E27 -> 15 | AA27: =J27+L27+N27+P27+W27+Y27+Z27 -> 89.333333 | AB27: 2 | AC27: =VLOOKUP(AB27,'Kriter Ağırlık'!$A$12:$C$17,3,0) -> 0 | AD27: 1 | AE27: =VLOOKUP(AD27,'Kriter Ağırlık'!$E$12:$G$24,3,0) -> 1 | AF27: =AA27*AC27*AE27 -> 0 | AG27: =VLOOKUP(A27,'Çalışan Listesi'!A:G,6,0) -> GRUP LİDERİ
A28: 124 | B28: ALİ KÜÇÜK | C28: 37088 | D28: =IF($AI$2-C28>=90,90,$AI$2-C28) -> 90 | E28: =D28/90 -> 1 | F28: AMBALAJ | G28: Paketleme Ambalaj Takım Lideri Yardımcıs | H28: =VLOOKUP(A28,'Çalışan Listesi'!A:G,7,0) -> 4.KADEME | I28: =IFERROR(VLOOKUP(A28,'Kaizen Listesi'!A:H,8,0),0) -> 66.666667 | J28: =I28*VLOOKUP($I$2,'Kriter Ağırlık'!$A$1:$B$8,2,0) -> 8 | K28: =IFERROR(VLOOKUP(A28,'Hata Kartı '!A:H,8,0),0) -> 100 | L28: =K28*(VLOOKUP($K$2,'Kriter Ağırlık'!$A$1:$B$8,2,0)) -> 10 | M28: =IFERROR(VLOOKUP(F28,'5S'!$B$8:$E$19,4,0),0) -> 1 | N28: =VLOOKUP(M28,'5S'!$G$8:$I$14,3,1)*VLOOKUP($M$2,'Kriter Ağırlık'!$A$1:$B$8,2,0)*E28*X28 -> 8 | O28: =IFERROR(VLOOKUP(A28,Devamsızlıklar!A:K,10,0),0) -> 0 | P28: =VLOOKUP(O28,Aralıklar!$A$2:$C$5,3,1)*VLOOKUP($O$2,'Kriter Ağırlık'!$A$1:$B$8,2,0)*E28*X28 -> 10 | Q28: =IFERROR(VLOOKUP(A28,Devamsızlıklar!A:K,8,0),0) -> 0 | R28: =VLOOKUP(Q28,Aralıklar!$E$2:$G$5,3,1) -> 1 | S28: =IFERROR(VLOOKUP(A28,Devamsızlıklar!A:K,9,0),0) -> 0 | T28: =VLOOKUP(S28,Aralıklar!$I$2:$K$6,3,1) -> 50 | U28: =IFERROR(VLOOKUP(A28,Devamsızlıklar!A:K,11,0),0) -> 0 | V28: =VLOOKUP(U28,Aralıklar!$M$2:$O$6,3,1) -> 50 | W28: =IF(X28=0,0,(T28+V28)*R28*VLOOKUP($W$2,'Kriter Ağırlık'!$A$1:$B$8,2,1)*E28) -> 10 | X28: =IFERROR(VLOOKUP(A28,Devamsızlıklar!A:M,13,0),1) -> 1 | Y28: =(OEE!$K$6*VLOOKUP($Y$2,'Kriter Ağırlık'!$A$1:$B$8,2,1))*X28*E28 -> 35 | Z28: =(TELEF!$I$10*VLOOKUP($Z$2,'Kriter Ağırlık'!$A$1:$B$8,2,1))*X28*E28 -> 15 | AA28: =J28+L28+N28+P28+W28+Y28+Z28 -> 96 | AB28: 4 | AC28: =VLOOKUP(AB28,'Kriter Ağırlık'!$A$12:$C$17,3,0) -> 13.5 | AD28: 1 | AE28: =VLOOKUP(AD28,'Kriter Ağırlık'!$E$12:$G$24,3,0) -> 1 | AF28: =AA28*AC28*AE28 -> 1296 | AG28: =VLOOKUP(A28,'Çalışan Listesi'!A:G,6,0) -> TAKIM LİDERİ YARDIMCISI
